Workbook
Name ANALYTES: #REF!
Name ANALYTES: '[1]validation de méthode'!$AD$6:$AD$461
Name ANALYTES: '[1]validation de méthode'!$AD$6:$AD$461
Name ANALYTES: '[1]validation de méthode'!$AD$6:$AD$461
Name ANALYTES: '[1]validation de méthode'!$AD$6:$AD$461
Name ANALYTES: #REF!

Sheet BCE - GRR
B2: GAGE R&R
G4: plan d'expériences croisée
C5: Facteur qualitatif | G5: X | H5: Y | I5: r1 | J5: r2 | K5: r3 | L5: r4 | M5: r5 | N5: r6
C6: X | D6: opérateur | G6: marie | H6: 1 | I6: 30.684 | J6: 30.436 | K6: 30.451 | O6: =+SUM(I6:N6) -> 91.571 | P6: Tolérance - | Q6: 25 | R6: =+Q6 -> 25 | S6: 0 | T6: =X63 -> 1.3559413 | U6: =VAR(I6:N6) -> 0.019336333
C7: Y | D7: pièce | H7: 2 | I7: 30.943 | J7: 30.408 | K7: 30.214 | O7: =+SUM(I7:N7) -> 91.565 | P7: Tolérance + | Q7: 35 | R7: =+Q7 -> 35 | S7: 0 | T7: =T6 -> 1.3559413 | U7: =VAR(I7:N7) -> 0.14255033
H8: 3 | I8: 30.896 | J8: 30.419 | K8: 30.374 | O8: =+SUM(I8:N8) -> 91.689 | U8: =VAR(I8:N8) -> 0.083673
C9: Les N observations sont obtenues sous | H9: 4 | I9: 30.989 | J9: 30.004 | K9: 30.272 | O9: =+SUM(I9:N9) -> 91.265 | P9: moyenne | Q9: =AVERAGE(I6:N35) -> 30.531644 | U9: =VAR(I9:N9) -> 0.25935633
C10: condition de répétabilité : même méthode, | H10: 5 | I10: 30.166 | J10: 30.826 | K10: 30.63 | O10: =+SUM(I10:N10) -> 91.622 | P10: S² totale | Q10: =I58 -> 0.086564209 | U10: =VAR(I10:N10) -> 0.11488533
C11: même sujet, laps de temps le plus | H11: 6 | I11: 30.515 | J11: 30.846 | K11: 30.019 | O11: =+SUM(I11:N11) -> 91.38 | P11: S totale | Q11: =SQRT(Q10) -> 0.29421796 | U11: =VAR(I11:N11) -> 0.173251
C12: court possible, | H12: 7 | I12: 30.382 | J12: 30.954 | K12: 30.677 | O12: =+SUM(I12:N12) -> 92.013 | P12: Min | Q12: =MIN(I6:N35) -> 30.001 | U12: =VAR(I12:N12) -> 0.081823
C13: Les pièces sont tirées au hasard et représentent | H13: 8 | I13: 30.431 | J13: 30.158 | K13: 30.007 | O13: =+SUM(I13:N13) -> 90.596 | P13: Max | Q13: =MAX(I6:N35) -> 30.993 | U13: =VAR(I13:N13) -> 0.046184333
C14: l'étendu des pièces observables (Cf et NC) | H14: 9 | I14: 30.7 | J14: 30.695 | K14: 30.634 | O14: =+SUM(I14:N14) -> 92.029 | U14: =VAR(I14:N14) -> 0.0013503333
H15: 10 | I15: 30.468 | J15: 30.108 | K15: 30.965 | O15: =+SUM(I15:N15) -> 91.541 | P15: Cpc | Q15: =(Q7-Q6)/(6*SQRT(K60)) -> 5.5325071 | R15: > 4 | U15: =VAR(I15:N15) -> 0.18517633
G16: pierre | H16: 1 | I16: 30.823 | J16: 30.93 | K16: 30.359 | O16: =+SUM(I16:N16) -> 92.112 | P16: *GRR% | Q16: =SQRT(N57)/((Q7-Q6)/6) -> 0.18074988 | R16: < 25% | U16: =VAR(I16:N16) -> 0.092131
H17: 2 | I17: 30.841 | J17: 30.378 | K17: 30.442 | O17: =+SUM(I17:N17) -> 91.661 | P17: *basé sur les Tolérances | U17: =VAR(I17:N17) -> 0.062944333
H18: 3 | I18: 30.981 | J18: 30.001 | K18: 30.648 | O18: =+SUM(I18:N18) -> 91.63 | U18: =VAR(I18:N18) -> 0.24831633
H19: 4 | I19: 30.689 | J19: 30.62 | K19: 30.429 | O19: =+SUM(I19:N19) -> 91.738 | P19: Cp méthode | Q19: =(Q7-Q6)/(6*SQRT(I58)) -> 5.6647346 | R19: > 1,33 | U19: =VAR(I19:N19) -> 0.018140333
H20: 5 | I20: 30.946 | J20: 30.406 | K20: 30.684 | O20: =+SUM(I20:N20) -> 92.036 | U20: =VAR(I20:N20) -> 0.072921333
H21: 6 | I21: 30.24 | J21: 30.829 | K21: 30.558 | O21: =+SUM(I21:N21) -> 91.627 | U21: =VAR(I21:N21) -> 0.086914333
H22: 7 | I22: 30.15 | J22: 30.61 | K22: 30.197 | O22: =+SUM(I22:N22) -> 90.957 | U22: =VAR(I22:N22) -> 0.064063
H23: 8 | I23: 30.722 | J23: 30.592 | K23: 30.66 | O23: =+SUM(I23:N23) -> 91.974 | U23: =VAR(I23:N23) -> 0.004228
H24: 9 | I24: 30.004 | J24: 30.59 | K24: 30.167 | O24: =+SUM(I24:N24) -> 90.761 | U24: =VAR(I24:N24) -> 0.091482333
H25: 10 | I25: 30.663 | J25: 30.759 | K25: 30.254 | O25: =+SUM(I25:N25) -> 91.676 | U25: =VAR(I25:N25) -> 0.071920333
G26: paul | H26: 1 | I26: 30.936 | J26: 30.686 | K26: 30.631 | O26: =+SUM(I26:N26) -> 92.253 | U26: =VAR(I26:N26) -> 0.026425
H27: 2 | I27: 30.136 | J27: 30.661 | K27: 30.216 | O27: =+SUM(I27:N27) -> 91.013 | U27: =VAR(I27:N27) -> 0.080008333
H28: 3 | I28: 30.714 | J28: 30.094 | K28: 30.204 | O28: =+SUM(I28:N28) -> 91.012 | U28: =VAR(I28:N28) -> 0.10943333
H29: 4 | I29: 30.449 | J29: 30.678 | K29: 30.993 | O29: =+SUM(I29:N29) -> 92.12 | U29: =VAR(I29:N29) -> 0.074600333
H30: 5 | I30: 30.892 | J30: 30.888 | K30: 30.344 | O30: =+SUM(I30:N30) -> 92.124 | U30: =VAR(I30:N30) -> 0.099376
H31: 6 | I31: 30.892 | J31: 30.033 | K31: 30.931 | O31: =+SUM(I31:N31) -> 91.856 | U31: =VAR(I31:N31) -> 0.25763433
H32: 7 | I32: 30.579 | J32: 30.365 | K32: 30.381 | O32: =+SUM(I32:N32) -> 91.325 | U32: =VAR(I32:N32) -> 0.014209333
H33: 8 | I33: 30.791 | J33: 30.471 | K33: 30.722 | O33: =+SUM(I33:N33) -> 91.984 | U33: =VAR(I33:N33) -> 0.028360333
H34: 9 | I34: 30.183 | J34: 30.203 | K34: 30.126 | O34: =+SUM(I34:N34) -> 90.512 | U34: =VAR(I34:N34) -> 0.0015963333 | V34: -3 | W34: =Q$9+V34*SQRT(Q$10) -> 29.648991 | X34: =NORMDIST(W34,Q$9,SQRT(Q$10),0) -> 0.015063147
H35: 10 | I35: 30.987 | J35: 30.359 | K35: 30.86 | O35: =+SUM(I35:N35) -> 92.206 | U35: =VAR(I35:N35) -> 0.11025233 | V35: -2.9 | W35: =Q$9+V35*SQRT(Q$10) -> 29.678412 | X35: =NORMDIST(W35,Q$9,SQRT(Q$10),0) -> 0.02023171
V36: -2.7 | W36: =Q$9+V36*SQRT(Q$10) -> 29.737256 | X36: =NORMDIST(W36,Q$9,SQRT(Q$10),0) -> 0.035419098
V37: -2.6 | W37: =Q$9+V37*SQRT(Q$10) -> 29.766678 | X37: =NORMDIST(W37,Q$9,SQRT(Q$10),0) -> 0.046166349
V38: -2.5 | W38: =Q$9+V38*SQRT(Q$10) -> 29.7961 | X38: =NORMDIST(W38,Q$9,SQRT(Q$10),0) -> 0.059575902
V39: -2.4 | W39: =Q$9+V39*SQRT(Q$10) -> 29.825521 | X39: =NORMDIST(W39,Q$9,SQRT(Q$10),0) -> 0.076115442
V40: -2.3 | W40: =Q$9+V40*SQRT(Q$10) -> 29.854943 | X40: =NORMDIST(W40,Q$9,SQRT(Q$10),0) -> 0.09627909
V41: -2.2 | W41: =Q$9+V41*SQRT(Q$10) -> 29.884365 | X41: =NORMDIST(W41,Q$9,SQRT(Q$10),0) -> 0.12057249
V42: -2.1 | W42: =Q$9+V42*SQRT(Q$10) -> 29.913787 | X42: =NORMDIST(W42,Q$9,SQRT(Q$10),0) -> 0.14949324
...

Sheet 1F5N
H3: X
C4: Facteur qualitatif | G4: n | H4: marie | I4: pierre | J4: paul | K4: jack | L4: sophie | P4: Cible | Q4: 20
C5: X | D5: opérateur | G5: 1 | H5: =20+RAND()*2 -> 21.670775 | I5: =20+RAND() -> 20.805161 | J5: =20+RAND()*2 -> 21.485642 | K5: =20+RAND() -> 20.450068 | L5: =20.5+RAND() -> 20.720537 | P5: Tolérance - | Q5: 19 | R5: =+Q5 -> 19 | S5: 0 | T5: =MAX(X41,Y41,Z41,AA41,AB41,AC41) -> 1.4198191
G6: 2 | H6: =20+RAND()*2 -> 21.292747 | I6: =20+RAND() -> 20.148927 | J6: =20+RAND()*2 -> 20.290667 | K6: =20+RAND() -> 20.909313 | L6: =20.5+RAND() -> 21.158884 | P6: Tolérance + | Q6: 22 | R6: =+Q6 -> 22 | S6: 0 | T6: =T5 -> 1.4198191
C7: les n obserations sont réalisées sous condition de | G7: 3 | H7: =20+RAND()*2 -> 21.071173 | I7: =20+RAND() -> 20.637408 | J7: =20+RAND()*2 -> 21.496459 | K7: =20+RAND() -> 20.813011 | L7: =20.5+RAND() -> 21.474109
C8: répétabilité : même méthode, même sujet, même | G8: 4 | H8: =20+RAND()*2 -> 21.520149 | I8: =20+RAND() -> 20.333781 | J8: =20+RAND()*2 -> 20.675013 | K8: =20+RAND() -> 20.889901 | L8: =20.5+RAND() -> 20.867228 | P8: moyenne | Q8: =AVERAGE(H5:L14) -> 20.866583
C9: équipement, temps d'étude le plus court possible | G9: 5 | H9: =20+RAND()*2 -> 21.675659 | I9: =20+RAND() -> 20.514495 | J9: =20+RAND()*2 -> 21.895642 | K9: =20+RAND() -> 20.682834 | L9: =20.5+RAND() -> 20.749153 | P9: S² totale | Q9: =I36 -> 0.2586149 | Y9: =AVERAGE(H5:H14) -> 21.357898 | Z9: =AVERAGE(I5:I14) -> 20.472705 | AA9: =AVERAGE(J5:J14) -> 21.07399 | AB9: =AVERAGE(K5:K14) -> 20.534537 | AC9: =AVERAGE(L5:L14) -> 20.893786
G10: 6 | H10: =20+RAND()*2 -> 20.562584 | I10: =20+RAND() -> 20.022511 | J10: =20+RAND()*2 -> 21.785685 | K10: =20+RAND() -> 20.312464 | L10: =20.5+RAND() -> 20.588016 | P10: S totale | Q10: =SQRT(Q9) -> 0.50854193 | Y10: =H15 -> 0.16023593 | Z10: =I15 -> 0.098095706 | AA10: =J15 -> 0.35386839 | AB10: =K15 -> 0.10589285 | AC10: =L15 -> 0.078206837
C11: Chaque opérateur à le même nombre de résultat | G11: 7 | H11: =20+RAND()*2 -> 21.357572 | I11: =20+RAND() -> 20.041734 | J11: =20+RAND()*2 -> 21.036912 | K11: =20+RAND() -> 20.806233 | L11: =20.5+RAND() -> 20.520465 | P11: Min | Q11: =MIN(H5:L14) -> 20.00893 | V11: -3 | W11: =Q$8+V11*SQRT(Q$9) -> 19.340957 | X11: =NORMDIST(W11,Q$8,SQRT(Q$9),0) -> 0.0087148141 | Y11: =NORMDIST($W11,Y$9,SQRT(Y$10),0) -> 3.0592892e-06 | Z11: =NORMDIST($W11,Z$9,SQRT(Z$10),0) -> 0.0018610443 | AA11: =NORMDIST($W11,AA$9,SQRT(AA$10),0) -> 0.0096269126 | AB11: =NORMDIST($W11,AB$9,SQRT(AB$10),0) -> 0.0014692036 | AC11: =NORMDIST($W11,AC$9,SQRT(AC$10),0) -> 2.8786731e-07
C12: Plan complet équilibré | G12: 8 | H12: =20+RAND()*2 -> 21.626551 | I12: =20+RAND() -> 20.725952 | J12: =20+RAND()*2 -> 20.914656 | K12: =20+RAND() -> 20.202098 | L12: =20.5+RAND() -> 20.920759 | P12: Max | Q12: =MAX(H5:L14) -> 21.895642 | V12: -2.9 | W12: =Q$8+V12*SQRT(Q$9) -> 19.391812 | X12: =NORMDIST(W12,Q$8,SQRT(Q$9),0) -> 0.011705097 | Y12: =NORMDIST($W12,Y$9,SQRT(Y$10),0) -> 5.7559314e-06 | Z12: =NORMDIST($W12,Z$9,SQRT(Z$10),0) -> 0.0033024672 | AA12: =NORMDIST($W12,AA$9,SQRT(AA$10),0) -> 0.012304455 | AB12: =NORMDIST($W12,AB$9,SQRT(AB$10),0) -> 0.0025746568 | AC12: =NORMDIST($W12,AC$9,SQRT(AC$10),0) -> 7.7719903e-07
G13: 9 | H13: =20+RAND()*2 -> 21.86028 | I13: =20+RAND() -> 20.663057 | J13: =20+RAND()*2 -> 21.007918 | K13: =20+RAND() -> 20.00893 | L13: =20.5+RAND() -> 20.978218 | N13: =SUM(I10:L10) -> 82.708675 | P13: Cpk | Q13: =MIN((Q6-Q8)/(3*SQRT(Q9)),(Q8-Q5)/(3*SQRT(Q9))) -> 0.74291932 | V13: -2.8 | W13: =Q$8+V13*SQRT(Q$9) -> 19.442666 | X13: =NORMDIST(W13,Q$8,SQRT(Q$9),0) -> 0.015564993 | Y13: =NORMDIST($W13,Y$9,SQRT(Y$10),0) -> 1.0656175e-05 | Z13: =NORMDIST($W13,Z$9,SQRT(Z$10),0) -> 0.0057078265 | AA13: =NORMDIST($W13,AA$9,SQRT(AA$10),0) -> 0.015612189 | AB13: =NORMDIST($W13,AB$9,SQRT(AB$10),0) -> 0.0044030157 | AC13: =NORMDIST($W13,AC$9,SQRT(AC$10),0) -> 2.0300694e-06
G14: 10 | H14: =20+RAND()*2 -> 20.941494 | I14: =20+RAND() -> 20.834022 | J14: =20+RAND()*2 -> 20.151303 | K14: =20+RAND() -> 20.270516 | L14: =20.5+RAND() -> 20.960492 | N14: =SUM(I11:L11) -> 82.405344 | V14: -2.7 | W14: =Q$8+V14*SQRT(Q$9) -> 19.49352 | X14: =NORMDIST(W14,Q$8,SQRT(Q$9),0) -> 0.020491791 | Y14: =NORMDIST($W14,Y$9,SQRT(Y$10),0) -> 1.9412332e-05 | Z14: =NORMDIST($W14,Z$9,SQRT(Z$10),0) -> 0.0096084533 | AA14: =NORMDIST($W14,AA$9,SQRT(AA$10),0) -> 0.019664881 | AB14: =NORMDIST($W14,AB$9,SQRT(AB$10),0) -> 0.0073480928 | AC14: =NORMDIST($W14,AC$9,SQRT(AC$10),0) -> 5.1301282e-06
G15: variance | H15: =VAR(H5:H14) -> 0.16023593 | I15: =VAR(I5:I14) -> 0.098095706 | J15: =VAR(J5:J14) -> 0.35386839 | K15: =VAR(K5:K14) -> 0.10589285 | L15: =VAR(L5:L14) -> 0.078206837 | V15: -2.6 | W15: =Q$8+V15*SQRT(Q$9) -> 19.544374 | X15: =NORMDIST(W15,Q$8,SQRT(Q$9),0) -> 0.026709635 | Y15: =NORMDIST($W15,Y$9,SQRT(Y$10),0) -> 3.4797233e-05 | Z15: =NORMDIST($W15,Z$9,SQRT(Z$10),0) -> 0.015753849 | AA15: =NORMDIST($W15,AA$9,SQRT(AA$10),0) -> 0.024589229 | AB15: =NORMDIST($W15,AB$9,SQRT(AB$10),0) -> 0.0119672 | AC15: =NORMDIST($W15,AC$9,SQRT(AC$10),0) -> 1.2542505e-05
V16: -2.5 | W16: =Q$8+V16*SQRT(Q$9) -> 19.595228 | X16: =NORMDIST(W16,Q$8,SQRT(Q$9),0) -> 0.034467758 | Y16: =NORMDIST($W16,Y$9,SQRT(Y$10),0) -> 6.1376537e-05 | Z16: =NORMDIST($W16,Z$9,SQRT(Z$10),0) -> 0.025157665 | AA16: =NORMDIST($W16,AA$9,SQRT(AA$10),0) -> 0.030522814 | AB16: =NORMDIST($W16,AB$9,SQRT(AB$10),0) -> 0.019019715 | AC16: =NORMDIST($W16,AC$9,SQRT(AC$10),0) -> 2.9667372e-05
V17: -2.4 | W17: =Q$8+V17*SQRT(Q$9) -> 19.646082 | X17: =NORMDIST(W17,Q$8,SQRT(Q$9),0) -> 0.044036743 | Y17: =NORMDIST($W17,Y$9,SQRT(Y$10),0) -> 0.00010652479 | Z17: =NORMDIST($W17,Z$9,SQRT(Z$10),0) -> 0.039129513 | AA17: =NORMDIST($W17,AA$9,SQRT(AA$10),0) -> 0.037612337 | AB17: =NORMDIST($W17,AB$9,SQRT(AB$10),0) -> 0.029499114 | AC17: =NORMDIST($W17,AC$9,SQRT(AC$10),0) -> 6.7891059e-05
V18: -2.3 | W18: =Q$8+V18*SQRT(Q$9) -> 19.696937 | X18: =NORMDIST(W18,Q$8,SQRT(Q$9),0) -> 0.055702462 | Y18: =NORMDIST($W18,Y$9,SQRT(Y$10),0) -> 0.00018192385 | Z18: =NORMDIST($W18,Z$9,SQRT(Z$10),0) -> 0.059277383 | AA18: =NORMDIST($W18,AA$9,SQRT(AA$10),0) -> 0.04601105 | AB18: =NORMDIST($W18,AB$9,SQRT(AB$10),0) -> 0.044648561 | AC18: =NORMDIST($W18,AC$9,SQRT(AC$10),0) -> 0.00015030894
V19: -2.2 | W19: =Q$8+V19*SQRT(Q$9) -> 19.747791 | X19: =NORMDIST(W19,Q$8,SQRT(Q$9),0) -> 0.069757459 | Y19: =NORMDIST($W19,Y$9,SQRT(Y$10),0) -> 0.00030571676 | Z19: =NORMDIST($W19,Z$9,SQRT(Z$10),0) -> 0.087462939 | AA19: =NORMDIST($W19,AA$9,SQRT(AA$10),0) -> 0.055875324 | AB19: =NORMDIST($W19,AB$9,SQRT(AB$10),0) -> 0.065947674 | AC19: =NORMDIST($W19,AC$9,SQRT(AC$10),0) -> 0.00032195544
V20: -2.1 | W20: =Q$8+V20*SQRT(Q$9) -> 19.798645 | X20: =NORMDIST(W20,Q$8,SQRT(Q$9),0) -> 0.086489615 | Y20: =NORMDIST($W20,Y$9,SQRT(Y$10),0) -> 0.00050552134 | Z20: =NORMDIST($W20,Z$9,SQRT(Z$10),0) -> 0.12569256 | AA20: =NORMDIST($W20,AA$9,SQRT(AA$10),0) -> 0.067360304 | AB20: =NORMDIST($W20,AB$9,SQRT(AB$10),0) -> 0.095057199 | AC20: =NORMDIST($W20,AC$9,SQRT(AC$10),0) -> 0.00066718371
V21: -2 | W21: =Q$8+V21*SQRT(Q$9) -> 19.849499 | X21: =NORMDIST(W21,Q$8,SQRT(Q$9),0) -> 0.10616817 | Y21: =NORMDIST($W21,Y$9,SQRT(Y$10),0) -> 0.00082252743 | Z21: =NORMDIST($W21,Z$9,SQRT(Z$10),0) -> 0.17593229 | AA21: =NORMDIST($W21,AA$9,SQRT(AA$10),0) -> 0.080614674 | AB21: =NORMDIST($W21,AB$9,SQRT(AB$10),0) -> 0.13371005 | AC21: =NORMDIST($W21,AC$9,SQRT(AC$10),0) -> 0.0013376233
V22: -1.9 | W22: =Q$8+V22*SQRT(Q$9) -> 19.900353 | X22: =NORMDIST(W22,Q$8,SQRT(Q$9),0) -> 0.12902734 | Y22: =NORMDIST($W22,Y$9,SQRT(Y$10),0) -> 0.0013168974 | Z22: =NORMDIST($W22,Z$9,SQRT(Z$10),0) -> 0.23984573 | AA22: =NORMDIST($W22,AA$9,SQRT(AA$10),0) -> 0.095774578 | AB22: =NORMDIST($W22,AB$9,SQRT(AB$10),0) -> 0.1835425 | AC22: =NORMDIST($W22,AC$9,SQRT(AC$10),0) -> 0.0025945434
V23: -1.8 | W23: =Q$8+V23*SQRT(Q$9) -> 19.951208 | X23: =NORMDIST(W23,Q$8,SQRT(Q$9),0) -> 0.15524808 | Y23: =NORMDIST($W23,Y$9,SQRT(Y$10),0) -> 0.0020746466 | Z23: =NORMDIST($W23,Z$9,SQRT(Z$10),0) -> 0.31847028 | AA23: =NORMDIST($W23,AA$9,SQRT(AA$10),0) -> 0.11295682 | AB23: =NORMDIST($W23,AB$9,SQRT(AB$10),0) -> 0.24586841 | AC23: =NORMDIST($W23,AC$9,SQRT(AC$10),0) -> 0.0048688542
V24: -1.7 | W24: =Q$8+V24*SQRT(Q$9) -> 20.002062 | X24: =NORMDIST(W24,Q$8,SQRT(Q$9),0) -> 0.18493869 | Y24: =NORMDIST($W24,Y$9,SQRT(Y$10),0) -> 0.0032160808 | Z24: =NORMDIST($W24,Z$9,SQRT(Z$10),0) -> 0.41186632 | AA24: =NORMDIST($W24,AA$9,SQRT(AA$10),0) -> 0.13225155 | AB24: =NORMDIST($W24,AB$9,SQRT(AB$10),0) -> 0.3214122 | AC24: =NORMDIST($W24,AC$9,SQRT(AC$10),0) -> 0.0088395738
V25: -1.6 | W25: =Q$8+V25*SQRT(Q$9) -> 20.052916 | X25: =NORMDIST(W25,Q$8,SQRT(Q$9),0) -> 0.21811542 | Y25: =NORMDIST($W25,Y$9,SQRT(Y$10),0) -> 0.0049056938 | Z25: =NORMDIST($W25,Z$9,SQRT(Z$10),0) -> 0.518793 | AA25: =NORMDIST($W25,AA$9,SQRT(AA$10),0) -> 0.15371461 | AB25: =NORMDIST($W25,AB$9,SQRT(AB$10),0) -> 0.41002987 | AC25: =NORMDIST($W25,AC$9,SQRT(AC$10),0) -> 0.015526537
V26: -1.5 | W26: =Q$8+V26*SQRT(Q$9) -> 20.10377 | X26: =NORMDIST(W26,Q$8,SQRT(Q$9),0) -> 0.2546842 | Y26: =NORMDIST($W26,Y$9,SQRT(Y$10),0) -> 0.0073631656 | Z26: =NORMDIST($W26,Z$9,SQRT(Z$10),0) -> 0.63647656 | AA26: =NORMDIST($W26,AA$9,SQRT(AA$10),0) -> 0.17735997 | AB26: =NORMDIST($W26,AB$9,SQRT(AB$10),0) -> 0.51046051 | AC26: =NORMDIST($W26,AC$9,SQRT(AC$10),0) -> 0.026384969
V27: -1.4 | W27: =Q$8+V27*SQRT(Q$9) -> 20.154624 | X27: =NORMDIST(W27,Q$8,SQRT(Q$9),0) -> 0.29442501 | Y27: =NORMDIST($W27,Y$9,SQRT(Y$10),0) -> 0.010874752 | Z27: =NORMDIST($W27,Z$9,SQRT(Z$10),0) -> 0.76053845 | AA27: =NORMDIST($W27,AA$9,SQRT(AA$10),0) -> 0.20315249 | AB27: =NORMDIST($W27,AB$9,SQRT(AB$10),0) -> 0.62015798 | AC27: =NORMDIST($W27,AC$9,SQRT(AC$10),0) -> 0.043378778
... V33: -0.8 | W33: =Q$8+V33*SQRT(Q$9) -> 20.45975 | X33: =NORMDIST(W33,Q$8,SQRT(Q$9),0) -> 0.56965126 | Y33: =NORMDIST($W33,Y$9,SQRT(Y$10),0) -> 0.080417687 | Z33: =NORMDIST($W33,Z$9,SQRT(Z$10),0) -> 1.2726634 | AA33: =NORMDIST($W33,AA$9,SQRT(AA$10),0) -> 0.39352203 | AB33: =NORMDIST($W33,AB$9,SQRT(AB$10),0) -> 1.1940083 | AC33: =NORMDIST($W33,AC$9,SQRT(AC$10),0) -> 0.42777436
C34: étape d'identification | G34: ANOVA | P34: Prérequis | V34: -0.7 | W34: =Q$8+V34*SQRT(Q$9) -> 20.510604 | X34: =NORMDIST(W34,Q$8,SQRT(Q$9),0) -> 0.61401807 | Y34: =NORMDIST($W34,Y$9,SQRT(Y$10),0) -> 0.1060818 | Z34: =NORMDIST($W34,Z$9,SQRT(Z$10),0) -> 1.2644613 | AA34: =NORMDIST($W34,AA$9,SQRT(AA$10),0) -> 0.42827049 | AB34: =NORMDIST($W34,AB$9,SQRT(AB$10),0) -> 1.2226501 | AC34: =NORMDIST($W34,AC$9,SQRT(AC$10),0) -> 0.55796442
C35: Origine | D35: niveau | E35: SB² | F35: CI | G35: SCE | H35: ddl | I35: CM | J35: Fobs | K35: F5% | L35: contrib% | M35: équiv β | N35: diff 1-β | P35: Cochran | V35: -0.6 | W35: =Q$8+V35*SQRT(Q$9) -> 20.561458 | X35: =NORMDIST(W35,Q$8,SQRT(Q$9),0) -> 0.65525492 | Y35: =NORMDIST($W35,Y$9,SQRT(Y$10),0) -> 0.13769584 | Z35: =NORMDIST($W35,Z$9,SQRT(Z$10),0) -> 1.2236242 | AA35: =NORMDIST($W35,AA$9,SQRT(AA$10),0) -> 0.46269342 | AB35: =NORMDIST($W35,AB$9,SQRT(AB$10),0) -> 1.2217731 | AC35: =NORMDIST($W35,AC$9,SQRT(AC$10),0) -> 0.70410429
C36: Total | D36: =COUNT(H5:L14) -> 50 | E36: =SUM(H5:L14)^2 -> 1088535.7 | F36: =E36/D36 -> 21770.715 | G36: =DEVSQ(H5:L14) -> 12.67213 | H36: =D36-1 -> 49 | I36: =G36/H36 -> 0.2586149 | J36: x | K36: x | L36: =SUM(L38:L40) -> 1 | M36: x | N36: x | P36: Cobs | Q36: =MAX(H15:L15)/SUM(H15:L15) -> 0.44439096 | V36: -0.5 | W36: =Q$8+V36*SQRT(Q$9) -> 20.612312 | X36: =NORMDIST(W36,Q$8,SQRT(Q$9),0) -> 0.69230344 | Y36: =NORMDIST($W36,Y$9,SQRT(Y$10),0) -> 0.17586986 | Z36: =NORMDIST($W36,Z$9,SQRT(Z$10),0) -> 1.1532966 | AA36: =NORMDIST($W36,AA$9,SQRT(AA$10),0) -> 0.4962432 | AB36: =NORMDIST($W36,AB$9,SQRT(AB$10),0) -> 1.1914407 | AC36: =NORMDIST($W36,AC$9,SQRT(AC$10),0) -> 0.85961937
C37: modèle | D37: x | E37: x | F37: x | G37: =SUM(G39) -> 5.5054326 | H37: =SUM(H39) -> 4 | I37: =G37/H37 -> 1.3763581 | J37: =I37/I38 -> 8.6422118 | K37: =FINV(0.05,H37,H38) -> 2.5787392 | L37: =G37/G36 -> 0.43445203 | M37: x | N37: x | P37: C 1% | Q37: =1/((1+(R46-1)/FINV(0.01/R46,R47-1,(R46)*(R47-1)))) -> 0.472136 | V37: -0.4 | W37: =Q$8+V37*SQRT(Q$9) -> 20.663166 | X37: =NORMDIST(W37,Q$8,SQRT(Q$9),0) -> 0.72416868 | Y37: =NORMDIST($W37,Y$9,SQRT(Y$10),0) -> 0.22103073 | Z37: =NORMDIST($W37,Z$9,SQRT(Z$10),0) -> 1.058728 | AA37: =NORMDIST($W37,AA$9,SQRT(AA$10),0) -> 0.52835023 | AB37: =NORMDIST($W37,AB$9,SQRT(AB$10),0) -> 1.1338296 | AC37: =NORMDIST($W37,AC$9,SQRT(AC$10),0) -> 1.0153461
C38: répéta | D38: x | E38: x | F38: x | G38: =G36-G37 -> 7.1666974 | H38: =H36-H37 -> 45 | I38: =G38/H38 -> 0.15925994 | J38: x | K38: x | L38: =G38/G36 -> 0.56554797 | M38: x | N38: x | P38: Cobs < C 1% = OK | V38: -0.3 | W38: =Q$8+V38*SQRT(Q$9) -> 20.714021 | X38: =NORMDIST(W38,Q$8,SQRT(Q$9),0) -> 0.74996336 | Y38: =NORMDIST($W38,Y$9,SQRT(Y$10),0) -> 0.27334086 | Z38: =NORMDIST($W38,Z$9,SQRT(Z$10),0) -> 0.9466257 | AA38: =NORMDIST($W38,AA$9,SQRT(AA$10),0) -> 0.55843845 | AB38: =NORMDIST($W38,AB$9,SQRT(AB$10),0) -> 1.0529718 | AC38: =NORMDIST($W38,AC$9,SQRT(AC$10),0) -> 1.1602745
C39: =D5 -> opérateur | D39: =COUNT(H5:L5) -> 5 | E39: =SUM(H5:H14)^2+SUM(I5:I14)^2+SUM(J5:J14)^2+SUM(K5:K14)^2+SUM(L5:L14)^2 -> 217762.2 | F39: =E39*D39/$D$36 -> 21776.22 | G39: =F39-$F$36 -> 5.5054326 | H39: =D39-1 -> 4 | I39: =G39/H39 -> 1.3763581 | J39: =I39/I$38 -> 8.6422118 | K39: =FINV(0.05,H39,H$38) -> 2.5787392 | L39: =G39/$G$36 -> 0.43445203 | M39: =1-FDIST(K39/J39,H39,H$38) -> 0.12253355 | N39: =1-M39 -> 0.87746645 | P39: Sinon variance aberrante | V39: -0.2 | W39: =Q$8+V39*SQRT(Q$9) -> 20.764875 | X39: =NORMDIST(W39,Q$8,SQRT(Q$9),0) -> 0.76894877 | Y39: =NORMDIST($W39,Y$9,SQRT(Y$10),0) -> 0.33261903 | Z39: =NORMDIST($W39,Z$9,SQRT(Z$10),0) -> 0.82437087 | AA39: =NORMDIST($W39,AA$9,SQRT(AA$10),0) -> 0.58594224 | AB39: =NORMDIST($W39,AB$9,SQRT(AB$10),0) -> 0.95428732 | AC39: =NORMDIST($W39,AC$9,SQRT(AC$10),0) -> 1.2827621
J40: Fobs < F5% = équivalence | V40: -0.1 | W40: =Q$8+V40*SQRT(Q$9) -> 20.815729 | X40: =NORMDIST(W40,Q$8,SQRT(Q$9),0) -> 0.78056994 | Y40: =NORMDIST($W40,Y$9,SQRT(Y$10),0) -> 0.39827246 | Z40: =NORMDIST($W40,Z$9,SQRT(Z$10),0) -> 0.6992258 | AA40: =NORMDIST($W40,AA$9,SQRT(AA$10),0) -> 0.6103239 | AB40: =NORMDIST($W40,AB$9,SQRT(AB$10),0) -> 0.84398575 | AC40: =NORMDIST($W40,AC$9,SQRT(AC$10),0) -> 1.3720509
C41: R² | D41: =L37 -> 0.43445203 | E41: <CoeffIcient de détermination : ce qui est expliqué par le modèle | V41: 0 | W41: =Q$8+V41*SQRT(Q$9) -> 20.866583 | X41: =NORMDIST(W41,Q$8,SQRT(Q$9),0) -> 0.78448257 | Y41: =NORMDIST($W41,Y$9,SQRT(Y$10),0) -> 0.46924981 | Z41: =NORMDIST($W41,Z$9,SQRT(Z$10),0) -> 0.57764727 | AA41: =NORMDIST($W41,AA$9,SQRT(AA$10),0) -> 0.63109106 | AB41: =NORMDIST($W41,AB$9,SQRT(AB$10),0) -> 0.72842457 | AC41: =NORMDIST($W41,AC$9,SQRT(AC$10),0) -> 1.4198191
K42: Fidélité | M42: IC 95% + | O42: Justesse | V42: 0.1 | W42: =Q$8+V42*SQRT(Q$9) -> 20.917437 | X42: =NORMDIST(W42,Q$8,SQRT(Q$9),0) -> 0.78056994 | Y42: =NORMDIST($W42,Y$9,SQRT(Y$10),0) -> 0.54402465 | Z42: =NORMDIST($W42,Z$9,SQRT(Z$10),0) -> 0.46479181 | AA42: =NORMDIST($W42,AA$9,SQRT(AA$10),0) -> 0.64781314 | AB42: =NORMDIST($W42,AB$9,SQRT(AB$10),0) -> 0.61351839 | AC42: =NORMDIST($W42,AC$9,SQRT(AC$10),0) -> 1.4214597
C43: R²ajusté | D43: =(I36-I38)/I36 -> 0.3841811 | E43: < expliqué par le modèle (ajusté) | K43: CV%r | L43: =SQRT(I38)/Q8 -> 0.019125022 | M43: =SQRT(_xlfn.CHISQ.INV(0.95,H38)/H38)*L43 -> 0.022386396 | O43: biais | P43: =Q8-Q4 -> 0.86658312 | V43: 0.2 | W43: =Q$8+V43*SQRT(Q$9) -> 20.968292 | X43: =NORMDIST(W43,Q$8,SQRT(Q$9),0) -> 0.76894877 | Y43: =NORMDIST($W43,Y$9,SQRT(Y$10),0) -> 0.62061705 | Z43: =NORMDIST($W43,Z$9,SQRT(Z$10),0) -> 0.36425428 | AA43: =NORMDIST($W43,AA$9,SQRT(AA$10),0) -> 0.66013622 | AB43: =NORMDIST($W43,AB$9,SQRT(AB$10),0) -> 0.50427113 | AC43: =NORMDIST($W43,AC$9,SQRT(AC$10),0) -> 1.3768125
K44: CV%Fi | L44: =IF(I36<I38,L43,SQRT(I36)/Q8) -> 0.024371117 | M44: =SQRT(_xlfn.CHISQ.INV(0.95,H36)/H36)*L44 -> 0.028357027 | O44: IC 95% | P44: =P43-TINV(0.05,H36)*Q10/SQRT(D36) -> 0.72205711 | Q44: =P43+TINV(0.05,H36)*Q10/SQRT(D36) -> 1.0111091 | V44: 0.3 | W44: =Q$8+V44*SQRT(Q$9) -> 21.019146 | X44: =NORMDIST(W44,Q$8,SQRT(Q$9),0) -> 0.74996336 | Y44: =NORMDIST($W44,Y$9,SQRT(Y$10),0) -> 0.69665775 | Z44: =NORMDIST($W44,Z$9,SQRT(Z$10),0) -> 0.2780362 | AA44: =NORMDIST($W44,AA$9,SQRT(AA$10),0) -> 0.66779544 | AB44: =NORMDIST($W44,AB$9,SQRT(AB$10),0) -> 0.4044773 | AC44: =NORMDIST($W44,AC$9,SQRT(AC$10),0) -> 1.2901903
C45: Catégorie | D45: =TRUNC(SQRT(I36/I38)*SQRT(2),0) -> 1 | E45: < nombre de catégorie détectable par la méthode | O45: Si contient 0, pas de biais significatif | V45: 0.4 | W45: =Q$8+V45*SQRT(Q$9) -> 21.07 | X45: =NORMDIST(W45,Q$8,SQRT(Q$9),0) -> 0.72416868 | Y45: =NORMDIST($W45,Y$9,SQRT(Y$10),0) -> 0.76949515 | Z45: =NORMDIST($W45,Z$9,SQRT(Z$10),0) -> 0.20670381 | AA45: =NORMDIST($W45,AA$9,SQRT(AA$10),0) -> 0.6706245 | AB45: =NORMDIST($W45,AB$9,SQRT(AB$10),0) -> 0.31660496 | AC45: =NORMDIST($W45,AC$9,SQRT(AC$10),0) -> 1.1696918
Q46: k | R46: =COUNT(H5:L5) -> 5 | V46: 0.5 | W46: =Q$8+V46*SQRT(Q$9) -> 21.120854 | X46: =NORMDIST(W46,Q$8,SQRT(Q$9),0) -> 0.69230344 | Y46: =NORMDIST($W46,Y$9,SQRT(Y$10),0) -> 0.83634015 | Z46: =NORMDIST($W46,Z$9,SQRT(Z$10),0) -> 0.1496739 | AA46: =NORMDIST($W46,AA$9,SQRT(AA$10),0) -> 0.66856165 | AB46: =NORMDIST($W46,AB$9,SQRT(AB$10),0) -> 0.24184371 | AC46: =NORMDIST($W46,AC$9,SQRT(AC$10),0) -> 1.025954
Q47: n | R47: =COUNT(H5:H14) -> 10 | V47: 0.6 | W47: =Q$8+V47*SQRT(Q$9) -> 21.171708 | X47: =NORMDIST(W47,Q$8,SQRT(Q$9),0) -> 0.65525492 | Y47: =NORMDIST($W47,Y$9,SQRT(Y$10),0) -> 0.89443886 | Z47: =NORMDIST($W47,Z$9,SQRT(Z$10),0) -> 0.10555873 | AA47: =NORMDIST($W47,AA$9,SQRT(AA$10),0) -> 0.66165193 | AB47: =NORMDIST($W47,AB$9,SQRT(AB$10),0) -> 0.18027911 | AC47: =NORMDIST($W47,AC$9,SQRT(AC$10),0) -> 0.8706087
...

Sheet BCH - GRR destructif
C3: Facteur qualitatif | G3: plan d'expériences emboité | L3: =SUM(H3:K3) -> 0 | M3: =SUM(I3:L3) -> 0
C4: X | D4: lot | E4: 3 | G4: X | H4: Y | I4: Z | J4: r1 | L4: Tolérance - | M4: 0 | N4: =M4 -> 0 | O4: 0 | P4: =R63 -> 0 | Q4: 0 | R4: =V63 -> 1.4584211
C5: Y | D5: opérateur | E5: 3 | G5: lot 1 | H5: Pierre | I5: pièce 1 | J5: =1+RAND() -> 1.3275995 | K5: =AVERAGE(J5:J7) -> 1.4076142 | L5: Tolérance + | M5: 3 | N5: =M5 -> 3 | O5: 0 | P5: =P4 -> 0 | Q5: 0 | R5: =R4 -> 1.4584211
C6: Z | D6: pièce | E6: 3 | I6: pièce 2 | J6: =1+RAND() -> 1.3139661
I7: pièce 3 | J7: =1+RAND() -> 1.5812771 | L7: moyenne | M7: =AVERAGE(J5:J31) -> 1.541676
C8: Lorsque le plan est emboité, on évalue | H8: Paul | I8: pièce 4 | J8: =1+RAND() -> 1.825683 | K8: =AVERAGE(J8:J10) -> 1.4736851 | L8: S² totale | M8: =I53 -> 0.074826294
C9: les variances intermédiaires de fidélité. | I9: pièce 5 | J9: =1+RAND() -> 1.4581128 | L9: S totale | M9: =SQRT(M8) -> 0.27354395
I10: pièce 6 | J10: =1+RAND() -> 1.1372595 | L10: Min | M10: =MIN(J5:J31) -> 1.0732488
C11: les facteurs opérateur et lot sont croisés | H11: Marie | I11: pièce 7 | J11: =1+RAND() -> 1.6777524 | K11: =AVERAGE(J11:J13) -> 1.8054869 | L11: Max | M11: =MAX(J5:J31) -> 1.9834304
C12: le facteur pièce est lui emboité dans Op/lot | I12: pièce 8 | J12: =1+RAND() -> 1.8592158
I13: pièce 9 | J13: =1+RAND() -> 1.8794925
G14: lot 2 | H14: Pierre | I14: pièce 10 | J14: =1+RAND() -> 1.4093734 | K14: =AVERAGE(J14:J16) -> 1.3979026
I15: pièce 11 | J15: =1+RAND() -> 1.7110856
I16: pièce 12 | J16: =1+RAND() -> 1.0732488
H17: Paul | I17: pièce 13 | J17: =1+RAND() -> 1.2944254 | K17: =AVERAGE(J17:J19) -> 1.7226873
I18: pièce 14 | J18: =1+RAND() -> 1.9148934
I19: pièce 15 | J19: =1+RAND() -> 1.9587431
H20: Marie | I20: pièce 16 | J20: =1+RAND() -> 1.5712214 | K20: =AVERAGE(J20:J22) -> 1.6236738
I21: pièce 17 | J21: =1+RAND() -> 1.4344293
I22: pièce 18 | J22: =1+RAND() -> 1.8653707
G23: lot 3 | H23: Pierre | I23: pièce 19 | J23: =1+RAND() -> 1.9834304 | K23: =AVERAGE(J23:J25) -> 1.5872155
I24: pièce 20 | J24: =1+RAND() -> 1.4842607
I25: pièce 21 | J25: =1+RAND() -> 1.2939554
H26: Paul | I26: pièce 22 | J26: =1+RAND() -> 1.4758071 | K26: =AVERAGE(J26:J28) -> 1.2969291
I27: pièce 23 | J27: =1+RAND() -> 1.3412372
I28: pièce 24 | J28: =1+RAND() -> 1.0737431
H29: Marie | I29: pièce 25 | J29: =1+RAND() -> 1.3339033 | K29: =AVERAGE(J29:J31) -> 1.5598893
I30: pièce 26 | J30: =1+RAND() -> 1.7149362
I31: pièce 27 | J31: =1+RAND() -> 1.6308284
T33: -3 | U33: =M$7+T33*SQRT(M$8) -> 0.72104412 | V33: =NORMDIST(U33,M$7,SQRT(M$8),0) -> 0.016201595
T34: -2.9 | U34: =M$7+T34*SQRT(M$8) -> 0.74839851 | V34: =NORMDIST(U34,M$7,SQRT(M$8),0) -> 0.02176079
T35: -2.8 | U35: =M$7+T35*SQRT(M$8) -> 0.77575291 | V35: =NORMDIST(U35,M$7,SQRT(M$8),0) -> 0.028936672
T36: -2.7 | U36: =M$7+T36*SQRT(M$8) -> 0.80310731 | V36: =NORMDIST(U36,M$7,SQRT(M$8),0) -> 0.038096016
T37: -2.6 | U37: =M$7+T37*SQRT(M$8) -> 0.8304617 | V37: =NORMDIST(U37,M$7,SQRT(M$8),0) -> 0.049655527
T38: -2.5 | U38: =M$7+T38*SQRT(M$8) -> 0.8578161 | V38: =NORMDIST(U38,M$7,SQRT(M$8),0) -> 0.064078552
T39: -2.4 | U39: =M$7+T39*SQRT(M$8) -> 0.88517049 | V39: =NORMDIST(U39,M$7,SQRT(M$8),0) -> 0.081868124
T40: -2.3 | U40: =M$7+T40*SQRT(M$8) -> 0.91252489 | V40: =NORMDIST(U40,M$7,SQRT(M$8),0) -> 0.10355571
T41: -2.2 | U41: =M$7+T41*SQRT(M$8) -> 0.93987928 | V41: =NORMDIST(U41,M$7,SQRT(M$8),0) -> 0.12968517
T42: -2.1 | U42: =M$7+T42*SQRT(M$8) -> 0.96723368 | V42: =NORMDIST(U42,M$7,SQRT(M$8),0) -> 0.1607917
T43: -2 | U43: =M$7+T43*SQRT(M$8) -> 0.99458807 | V43: =NORMDIST(U43,M$7,SQRT(M$8),0) -> 0.19737584
...

Sheet Plan hierarchisé
C3: ATTENTION: il faut le même nombre de niveau par facteur
C4: Facteurs testés
C5: A | D5: B | E5: C | F5: répétitions (2 obligatoires) | J5: total | L5: Identification | P5: ANOVA emboitée
C6: jour 1 | D6: labo 1 | E6: op 1 | F6: 101 | G6: 101 | H6: 101 | I6: =H6+RAND() -> 101.69125 | J6: =SUM(F6:I6) -> 404.69125 | K6: =DEVSQ(F6:I6) -> 0.35837197 | L6: Origine | M6: niveau | N6: SB² | O6: Ci | P6: SCE | Q6: ddl | R6: CM | S6: Fobs | T6: F5% | U6: contribution
E7: op 2 | F7: 101 | G7: 101 | H7: 101 | I7: =H7+RAND() -> 101.04514 | J7: =SUM(F7:I7) -> 404.04514 | K7: =DEVSQ(F7:I7) -> 0.0015284626 | L7: Total | M7: =COUNT(F6:I32) -> 108 | N7: =SUM(F6:I32)^2 -> 1.1928265e+08 | O7: =N7/M7 -> 1104469 | P7: =DEVSQ(F6:I32) -> 771.97585 | Q7: =M7-1 -> 107 | R7: =P7/Q7 -> 7.2147275 | S7: x | T7: x | U7: =SUM(U9:U12) -> 1
E8: op 3 | F8: 100 | G8: 100 | H8: 100 | I8: =H8+RAND() -> 100.33552 | J8: =SUM(F8:I8) -> 400.33552 | K8: =DEVSQ(F8:I8) -> 0.084431862 | L8: modèle | M8: x | N8: x | O8: x | P8: =SUM(P10:P12) -> 764.82619 | Q8: =SUM(Q10:Q12) -> 26 | R8: =P8/Q8 -> 29.416392 | S8: =R8/R9 -> 333.26469 | T8: =FINV(0.05,Q8,$Q$9) -> 1.6327336 | U8: =P8/$P$7 -> 0.9907385
D9: labo 2 | E9: op 1 | F9: 100 | G9: 100 | H9: 100 | I9: =H9+RAND() -> 100.98815 | J9: =SUM(F9:I9) -> 400.98815 | K9: =DEVSQ(F9:I9) -> 0.73232839 | L9: résiduel | M9: x | N9: x | O9: x | P9: =P7-P8 -> 7.1496555 | Q9: =Q7-SUM(Q10:Q12) -> 81 | R9: =P9/Q9 -> 0.088267352 | S9: x | T9: x | U9: =P9/$P$7 -> 0.0092615015
E10: op 2 | F10: 98 | G10: 98 | H10: 98 | I10: =H10+RAND() -> 98.01687 | J10: =SUM(F10:I10) -> 392.01687 | K10: =DEVSQ(F10:I10) -> 0.00021344753 | L10: A | M10: 3 | N10: =SUM(F6:I14)^2+SUM(F15:I23)^2+SUM(F24:I32)^2 -> 39762313 | O10: =N10*M10/M7 -> 1104508.7 | P10: =O10-O7 -> 39.720359 | Q10: =M10-1 -> 2 | R10: =P10/Q10 -> 19.86018 | S10: =R10/R11 -> 0.21110306 | T10: =FINV(0.05,Q10,Q11) -> 5.1432528 | U10: =P10/$P$7 -> 0.051452853
E11: op 3 | F11: 105 | G11: 105 | H11: 105 | I11: =H11+RAND() -> 105.2737 | J11: =SUM(F11:I11) -> 420.2737 | K11: =DEVSQ(F11:I11) -> 0.056183478 | L11: B/A | M11: =3*M10 -> 9 | N11: =SUM(F6:I8)^2+SUM(F9:I11)^2+SUM(F12:I14)^2+SUM(F15:I17)^2+SUM(F18:I20)^2+SUM(F21:I23)^2+SUM(F24:I26)^2+SUM(F27:I29)^2+SUM(F30:I32)^2 -> 13260878 | O11: =N11*M11/M7 -> 1105073.2 | P11: =O11-O10 -> 564.46873 | Q11: =M11-M10 -> 6 | R11: =P11/Q11 -> 94.078121 | S11: =R11/R12 -> 10.541812 | T11: =FINV(0.05,Q11,Q12) -> 2.6613045 | U11: =P11/$P$7 -> 0.73119999
D12: labo 3 | E12: op 1 | F12: 105 | G12: 105 | H12: 105 | I12: =H12+RAND() -> 105.37937 | J12: =SUM(F12:I12) -> 420.37937 | K12: =DEVSQ(F12:I12) -> 0.10794018 | L12: C/B/A | M12: =3*M11 -> 27 | N12: =SUMSQ(J6:J32) -> 4420935.2 | O12: =N12*M12/M7 -> 1105233.8 | P12: =O12-O11 -> 160.6371 | Q12: =M12-M11 -> 18 | R12: =P12/Q12 -> 8.9242835 | S12: =R12/R9 -> 101.10515 | T12: =FINV(0.05,Q12,Q9) -> 1.7326074 | U12: =P12/$P$7 -> 0.20808566
E13: op 2 | F13: 103 | G13: 103 | H13: 103 | I13: =H13+RAND() -> 103.0043 | J13: =SUM(F13:I13) -> 412.0043 | K13: =DEVSQ(F13:I13) -> 1.3882491e-05
E14: op 3 | F14: 104 | G14: 104 | H14: 104 | I14: =H14+RAND() -> 104.36913 | J14: =SUM(F14:I14) -> 416.36913 | K14: =DEVSQ(F14:I14) -> 0.10219473 | L14: R² | N14: categorie
C15: jour 2 | D15: labo 1 | E15: op 1 | F15: 99 | G15: 99 | H15: 99 | I15: =H15+RAND() -> 99.392368 | J15: =SUM(F15:I15) -> 396.39237 | K15: =DEVSQ(F15:I15) -> 0.11546453 | L15: =(P7-P9)/P7 -> 0.9907385 | N15: =TRUNC(SQRT(P7/P9)*1.41,0) -> 14 | O15: > 5
E16: op 2 | F16: 98 | G16: 98 | H16: 98 | I16: =H16+RAND() -> 98.576117 | J16: =SUM(F16:I16) -> 392.57612 | K16: =DEVSQ(F16:I16) -> 0.24893352
E17: op 3 | F17: 100 | G17: 100 | H17: 100 | I17: =H17+RAND() -> 100.44531 | J17: =SUM(F17:I17) -> 400.44531 | K17: =DEVSQ(F17:I17) -> 0.1487257 | L17: R²a
D18: labo 2 | E18: op 1 | F18: 99 | G18: 99 | H18: 99 | I18: =H18+RAND() -> 99.964604 | J18: =SUM(F18:I18) -> 396.9646 | K18: =DEVSQ(F18:I18) -> 0.69784561 | L18: =(R7-R9)/R7 -> 0.98776567
E19: op 2 | F19: 98 | G19: 98 | H19: 98 | I19: =H19+RAND() -> 98.943586 | J19: =SUM(F19:I19) -> 392.94359 | K19: =DEVSQ(F19:I19) -> 0.66776592
E20: op 3 | F20: 98 | G20: 98 | H20: 98 | I20: =H20+RAND() -> 98.555343 | J20: =SUM(F20:I20) -> 392.55534 | K20: =DEVSQ(F20:I20) -> 0.23130426
D21: labo 3 | E21: op 1 | F21: 104 | G21: 104 | H21: 104 | I21: =H21+RAND() -> 104.67515 | J21: =SUM(F21:I21) -> 416.67515 | K21: =DEVSQ(F21:I21) -> 0.34187469
E22: op 2 | F22: 105 | G22: 105 | H22: 105 | I22: =H22+RAND() -> 105.17417 | J22: =SUM(F22:I22) -> 420.17417 | K22: =DEVSQ(F22:I22) -> 0.022751867
E23: op 3 | F23: 105 | G23: 105 | H23: 105 | I23: =H23+RAND() -> 105.42169 | J23: =SUM(F23:I23) -> 420.42169 | K23: =DEVSQ(F23:I23) -> 0.13336796
C24: jour 3 | D24: labo 1 | E24: op 1 | F24: 98 | G24: 98 | H24: 98 | I24: =H24+RAND() -> 98.881009 | J24: =SUM(F24:I24) -> 392.88101 | K24: =DEVSQ(F24:I24) -> 0.58213271
E25: op 2 | F25: 99 | G25: 99 | H25: 99 | I25: =H25+RAND() -> 99.138327 | J25: =SUM(F25:I25) -> 396.13833 | K25: =DEVSQ(F25:I25) -> 0.014350872
E26: op 3 | F26: 98 | G26: 98 | H26: 98 | I26: =H26+RAND() -> 98.508759 | J26: =SUM(F26:I26) -> 392.50876 | K26: =DEVSQ(F26:I26) -> 0.19412643
D27: labo 2 | E27: op 1 | F27: 100 | G27: 100 | H27: 100 | I27: =H27+RAND() -> 100.39269 | J27: =SUM(F27:I27) -> 400.39269 | K27: =DEVSQ(F27:I27) -> 0.11565523
E28: op 2 | F28: 98 | G28: 98 | H28: 98 | I28: =H28+RAND() -> 98.107424 | J28: =SUM(F28:I28) -> 392.10742 | K28: =DEVSQ(F28:I28) -> 0.0086549357
E29: op 3 | F29: 100 | G29: 100 | H29: 100 | I29: =H29+RAND() -> 100.76206 | J29: =SUM(F29:I29) -> 400.76206 | K29: =DEVSQ(F29:I29) -> 0.43555124
D30: labo 3 | E30: op 1 | F30: 104 | G30: 104 | H30: 104 | I30: =H30+RAND() -> 104.96201 | J30: =SUM(F30:I30) -> 416.96201 | K30: =DEVSQ(F30:I30) -> 0.69410274
E31: op 2 | F31: 102 | G31: 102 | H31: 102 | I31: =H31+RAND() -> 102.95949 | J31: =SUM(F31:I31) -> 408.95949 | K31: =DEVSQ(F31:I31) -> 0.69046641
E32: op 3 | F32: 105 | G32: 105 | H32: 105 | I32: =H32+RAND() -> 105.69606 | J32: =SUM(F32:I32) -> 420.69606 | K32: =DEVSQ(F32:I32) -> 0.36337445
J33: SCE res | K33: =SUM(K6:K32) -> 7.1496555

Sheet Kruskal et Wallis
B2: Analyse de variance à 1 facteur
B4: il faut N>= 15 sinon il faut utiliser des tables spéciales
B5: Kruskal et Wallis
B6: lot | C6: obs | D6: Rang | E6: somme | F6: somme²/n | H6: obs | I6: rang | J6: répét | K6: double | L6: triple | M6: bilan
B7: A | C7: 10.1 | D7: =M7 -> 2 | E7: =SUM(D7:D11) -> 39.5 | F7: =E7^2/COUNT(C7:C11) -> 312.05 | H7: =C7 -> 10.1 | I7: =RANK(H7,$C$7:$C$21,1) -> 2 | J7: =COUNTIF($I$7:$I$21,$I$7:$I$21) -> 1 | K7: =IF(J7=2,(I7*2+1)/2,"") | L7: =IF(J7=3,(I7*3+3)/3,"") | M7: =IF(J7=1,I7,IF(J7=2,K7,IF(J7=3,L7,""))) -> 2
C8: 12.5 | D8: =M8 -> 10 | H8: =C8 -> 12.5 | I8: =RANK(H8,$C$7:$C$21,1) -> 9 | J8: =COUNTIF($I$7:$I$21,$I$7:$I$21) -> 3 | K8: =IF(J8=2,(I8*2+1)/2,"") | L8: =IF(J8=3,(I8*3+3)/3,"") -> 10 | M8: =IF(J8=1,I8,IF(J8=2,K8,IF(J8=3,L8,""))) -> 10
C9: 13 | D9: =M9 -> 13.5 | H9: =C9 -> 13 | I9: =RANK(H9,$C$7:$C$21,1) -> 13 | J9: =COUNTIF($I$7:$I$21,$I$7:$I$21) -> 2 | K9: =IF(J9=2,(I9*2+1)/2,"") -> 13.5 | L9: =IF(J9=3,(I9*3+3)/3,"") | M9: =IF(J9=1,I9,IF(J9=2,K9,IF(J9=3,L9,""))) -> 13.5
C10: 11.8 | D10: =M10 -> 6 | H10: =C10 -> 11.8 | I10: =RANK(H10,$C$7:$C$21,1) -> 6 | J10: =COUNTIF($I$7:$I$21,$I$7:$I$21) -> 1 | K10: =IF(J10=2,(I10*2+1)/2,"") | L10: =IF(J10=3,(I10*3+3)/3,"") | M10: =IF(J10=1,I10,IF(J10=2,K10,IF(J10=3,L10,""))) -> 6
C11: 12.2 | D11: =M11 -> 8 | H11: =C11 -> 12.2 | I11: =RANK(H11,$C$7:$C$21,1) -> 8 | J11: =COUNTIF($I$7:$I$21,$I$7:$I$21) -> 1 | K11: =IF(J11=2,(I11*2+1)/2,"") | L11: =IF(J11=3,(I11*3+3)/3,"") | M11: =IF(J11=1,I11,IF(J11=2,K11,IF(J11=3,L11,""))) -> 8
B12: B | C12: 10 | D12: =M12 -> 1 | E12: =SUM(D12:D16) -> 23 | F12: =E12^2/COUNT(C12:C16) -> 105.8 | H12: =C12 -> 10 | I12: =RANK(H12,$C$7:$C$21,1) -> 1 | J12: =COUNTIF($I$7:$I$21,$I$7:$I$21) -> 1 | K12: =IF(J12=2,(I12*2+1)/2,"") | L12: =IF(J12=3,(I12*3+3)/3,"") | M12: =IF(J12=1,I12,IF(J12=2,K12,IF(J12=3,L12,""))) -> 1
C13: 11.4 | D13: =M13 -> 4 | H13: =C13 -> 11.4 | I13: =RANK(H13,$C$7:$C$21,1) -> 4 | J13: =COUNTIF($I$7:$I$21,$I$7:$I$21) -> 1 | K13: =IF(J13=2,(I13*2+1)/2,"") | L13: =IF(J13=3,(I13*3+3)/3,"") | M13: =IF(J13=1,I13,IF(J13=2,K13,IF(J13=3,L13,""))) -> 4
C14: 12.5 | D14: =M14 -> 10 | H14: =C14 -> 12.5 | I14: =RANK(H14,$C$7:$C$21,1) -> 9 | J14: =COUNTIF($I$7:$I$21,$I$7:$I$21) -> 3 | K14: =IF(J14=2,(I14*2+1)/2,"") | L14: =IF(J14=3,(I14*3+3)/3,"") -> 10 | M14: =IF(J14=1,I14,IF(J14=2,K14,IF(J14=3,L14,""))) -> 10
C15: 11.5 | D15: =M15 -> 5 | H15: =C15 -> 11.5 | I15: =RANK(H15,$C$7:$C$21,1) -> 5 | J15: =COUNTIF($I$7:$I$21,$I$7:$I$21) -> 1 | K15: =IF(J15=2,(I15*2+1)/2,"") | L15: =IF(J15=3,(I15*3+3)/3,"") | M15: =IF(J15=1,I15,IF(J15=2,K15,IF(J15=3,L15,""))) -> 5
C16: 10.3 | D16: =M16 -> 3 | H16: =C16 -> 10.3 | I16: =RANK(H16,$C$7:$C$21,1) -> 3 | J16: =COUNTIF($I$7:$I$21,$I$7:$I$21) -> 1 | K16: =IF(J16=2,(I16*2+1)/2,"") | L16: =IF(J16=3,(I16*3+3)/3,"") | M16: =IF(J16=1,I16,IF(J16=2,K16,IF(J16=3,L16,""))) -> 3
B17: C | C17: 12.7 | D17: =M17 -> 12 | E17: =SUM(D17:D21) -> 57.5 | F17: =E17^2/COUNT(C17:C21) -> 661.25 | H17: =C17 -> 12.7 | I17: =RANK(H17,$C$7:$C$21,1) -> 12 | J17: =COUNTIF($I$7:$I$21,$I$7:$I$21) -> 1 | K17: =IF(J17=2,(I17*2+1)/2,"") | L17: =IF(J17=3,(I17*3+3)/3,"") | M17: =IF(J17=1,I17,IF(J17=2,K17,IF(J17=3,L17,""))) -> 12
C18: 12.5 | D18: =M18 -> 10 | H18: =C18 -> 12.5 | I18: =RANK(H18,$C$7:$C$21,1) -> 9 | J18: =COUNTIF($I$7:$I$21,$I$7:$I$21) -> 3 | K18: =IF(J18=2,(I18*2+1)/2,"") | L18: =IF(J18=3,(I18*3+3)/3,"") -> 10 | M18: =IF(J18=1,I18,IF(J18=2,K18,IF(J18=3,L18,""))) -> 10
C19: 13.5 | D19: =M19 -> 15 | H19: =C19 -> 13.5 | I19: =RANK(H19,$C$7:$C$21,1) -> 15 | J19: =COUNTIF($I$7:$I$21,$I$7:$I$21) -> 1 | K19: =IF(J19=2,(I19*2+1)/2,"") | L19: =IF(J19=3,(I19*3+3)/3,"") | M19: =IF(J19=1,I19,IF(J19=2,K19,IF(J19=3,L19,""))) -> 15
C20: 12.1 | D20: =M20 -> 7 | H20: =C20 -> 12.1 | I20: =RANK(H20,$C$7:$C$21,1) -> 7 | J20: =COUNTIF($I$7:$I$21,$I$7:$I$21) -> 1 | K20: =IF(J20=2,(I20*2+1)/2,"") | L20: =IF(J20=3,(I20*3+3)/3,"") | M20: =IF(J20=1,I20,IF(J20=2,K20,IF(J20=3,L20,""))) -> 7
C21: 13 | D21: =M21 -> 13.5 | H21: =C21 -> 13 | I21: =RANK(H21,$C$7:$C$21,1) -> 13 | J21: =COUNTIF($I$7:$I$21,$I$7:$I$21) -> 2 | K21: =IF(J21=2,(I21*2+1)/2,"") -> 13.5 | L21: =IF(J21=3,(I21*3+3)/3,"") | M21: =IF(J21=1,I21,IF(J21=2,K21,IF(J21=3,L21,""))) -> 13.5
B22: vérification | C22: =IF(E7+E12+E17=(COUNT(C7:C21)*(COUNT(C7:C21)+1))/2,"rang bien attribué","rang mal attribué") -> rang bien attribué | J22: x | K22: =COUNT(K7:K21) -> 2 | L22: =COUNT(L7:L21) -> 3
B23: X² brut | C23: =(12/(2*(E7+E12+E17)))*(F7+F12+F17)-3*(COUNT(C7:C21)+1) -> 5.955 | D23: facteur correctif | F23: =1-(K22*K23*(K22^2-1)+L22*L23*(L22^2-1))/(COUNT(C7:C21)*(COUNT(C7:C21)^2-1)) -> 0.99107143 | J23: y | K23: =COUNT(K7:K21)-1 -> 1 | L23: =COUNT(L7:L21)-2 -> 1
B24: X² corrigé | C24: =C23/F23 -> 6.0086486 | D24: X² 5%,ddl | E24: =_xlfn.CHISQ.INV(0.95,2) -> 5.9914645 | F24: =IF(C24<E24,"OK","Différence") -> Différence | J24: x=2 si doublon et 3 si triplon
B25: *Si différence, il existe au moins 2 différences parmis les | J25: y=nombre de doublon/triplon
B26: n facteur

Sheet Friedmann 
B3: Friedmann | D3: Facteur 2 = méthode | K3: rang corrigé*
D4: A | E4: B | F4: C | G4: rang | J4: total* | K4: =SUM(K5:K14) -> 26 | L4: =SUM(L5:L14) -> 16.5 | M4: =SUM(M5:M14) -> 17.5 | N4: somme | P4: Quand la colonne total affiche autre chose que OK
B5: Facteur 1 = lot | C5: 1 | D5: 9 | E5: 8 | F5: 10 | G5: =RANK(D5,$D5:$F5,1) -> 2 | H5: =RANK(E5,$D5:$F5,1) -> 1 | I5: =RANK(F5,$D5:$F5,1) -> 3 | J5: =IF(SUM(G5:I5)=6,"OK",IF(SUM(G5:I5)=5,"doublon",IF(SUM(G5:I5)=3,"triplon",""))) -> OK | K5: =IF($J5="ok",G5,IF(J5="triplon",2,"")) -> 2 | L5: =IF($J5="ok",H5,IF(J5="triplon",2,"")) -> 1 | M5: =IF($J5="ok",I5,IF(J5="triplon",2,"")) -> 3 | N5: =SUM(K5:M5) -> 6 | O5: =SUM(D5:F5) -> 27 | P5: ajouter, dans les colonnes rang corrigé, manuellement 0,5 aux doublons
C6: 2 | D6: 13 | E6: 13 | F6: 12 | G6: =RANK(D6,$D6:$F6,1) -> 2 | H6: =RANK(E6,$D6:$F6,1) -> 2 | I6: =RANK(F6,$D6:$F6,1) -> 1 | J6: =IF(SUM(G6:I6)=6,"OK",IF(SUM(G6:I6)=5,"doublon",IF(SUM(G6:I6)=3,"triplon",""))) -> doublon | K6: 2.5 | L6: 2.5 | M6: 1 | N6: =SUM(K6:M6) -> 6 | O6: =SUM(D6:F6) -> 38 | P6: 1 au triplon, etc
C7: 3 | D7: 12 | E7: 11 | F7: 10 | G7: =RANK(D7,$D7:$F7,1) -> 3 | H7: =RANK(E7,$D7:$F7,1) -> 2 | I7: =RANK(F7,$D7:$F7,1) -> 1 | J7: =IF(SUM(G7:I7)=6,"OK",IF(SUM(G7:I7)=5,"doublon",IF(SUM(G7:I7)=3,"triplon",""))) -> OK | K7: =IF($J7="ok",G7,IF(J7="triplon",2,"")) -> 3 | L7: =IF($J7="ok",H7,IF(J7="triplon",2,"")) -> 2 | M7: =IF($J7="ok",I7,IF(J7="triplon",2,"")) -> 1 | N7: =SUM(K7:M7) -> 6 | O7: =SUM(D7:F7) -> 33
C8: 4 | D8: 10 | E8: 9 | F8: 8 | G8: =RANK(D8,$D8:$F8,1) -> 3 | H8: =RANK(E8,$D8:$F8,1) -> 2 | I8: =RANK(F8,$D8:$F8,1) -> 1 | J8: =IF(SUM(G8:I8)=6,"OK",IF(SUM(G8:I8)=5,"doublon",IF(SUM(G8:I8)=3,"triplon",""))) -> OK | K8: =IF($J8="ok",G8,IF(J8="triplon",2,"")) -> 3 | L8: =IF($J8="ok",H8,IF(J8="triplon",2,"")) -> 2 | M8: =IF($J8="ok",I8,IF(J8="triplon",2,"")) -> 1 | N8: =SUM(K8:M8) -> 6 | O8: =SUM(D8:F8) -> 27
C9: 5 | D9: 14 | E9: 12 | F9: 13 | G9: =RANK(D9,$D9:$F9,1) -> 3 | H9: =RANK(E9,$D9:$F9,1) -> 1 | I9: =RANK(F9,$D9:$F9,1) -> 2 | J9: =IF(SUM(G9:I9)=6,"OK",IF(SUM(G9:I9)=5,"doublon",IF(SUM(G9:I9)=3,"triplon",""))) -> OK | K9: =IF($J9="ok",G9,IF(J9="triplon",2,"")) -> 3 | L9: =IF($J9="ok",H9,IF(J9="triplon",2,"")) -> 1 | M9: =IF($J9="ok",I9,IF(J9="triplon",2,"")) -> 2 | N9: =SUM(K9:M9) -> 6 | O9: =SUM(D9:F9) -> 39
C10: 6 | D10: 11 | E10: 9 | F10: 9 | G10: =RANK(D10,$D10:$F10,1) -> 3 | H10: =RANK(E10,$D10:$F10,1) -> 1 | I10: =RANK(F10,$D10:$F10,1) -> 1 | J10: =IF(SUM(G10:I10)=6,"OK",IF(SUM(G10:I10)=5,"doublon",IF(SUM(G10:I10)=3,"triplon",""))) -> doublon | K10: 3 | L10: 1.5 | M10: 1.5 | N10: =SUM(K10:M10) -> 6 | O10: =SUM(D10:F10) -> 29
C11: 7 | D11: 9 | E11: 9 | F11: 8 | G11: =RANK(D11,$D11:$F11,1) -> 2 | H11: =RANK(E11,$D11:$F11,1) -> 2 | I11: =RANK(F11,$D11:$F11,1) -> 1 | J11: =IF(SUM(G11:I11)=6,"OK",IF(SUM(G11:I11)=5,"doublon",IF(SUM(G11:I11)=3,"triplon",""))) -> doublon | K11: 2.5 | L11: 2.5 | M11: 1 | N11: =SUM(K11:M11) -> 6 | O11: =SUM(D11:F11) -> 26
C12: 8 | D12: 12 | E12: 11 | F12: 12 | G12: =RANK(D12,$D12:$F12,1) -> 2 | H12: =RANK(E12,$D12:$F12,1) -> 1 | I12: =RANK(F12,$D12:$F12,1) -> 2 | J12: =IF(SUM(G12:I12)=6,"OK",IF(SUM(G12:I12)=5,"doublon",IF(SUM(G12:I12)=3,"triplon",""))) -> doublon | K12: 2.5 | L12: 1 | M12: 2.5 | N12: =SUM(K12:M12) -> 6 | O12: =SUM(D12:F12) -> 35
C13: 9 | D13: 9 | E13: 9 | F13: 10 | G13: =RANK(D13,$D13:$F13,1) -> 1 | H13: =RANK(E13,$D13:$F13,1) -> 1 | I13: =RANK(F13,$D13:$F13,1) -> 3 | J13: =IF(SUM(G13:I13)=6,"OK",IF(SUM(G13:I13)=5,"doublon",IF(SUM(G13:I13)=3,"triplon",""))) -> doublon | K13: 1.5 | L13: 1.5 | M13: 3 | N13: =SUM(K13:M13) -> 6 | O13: =SUM(D13:F13) -> 28
C14: 10 | D14: 7 | E14: 6 | F14: 6 | G14: =RANK(D14,$D14:$F14,1) -> 3 | H14: =RANK(E14,$D14:$F14,1) -> 1 | I14: =RANK(F14,$D14:$F14,1) -> 1 | J14: =IF(SUM(G14:I14)=6,"OK",IF(SUM(G14:I14)=5,"doublon",IF(SUM(G14:I14)=3,"triplon",""))) -> doublon | K14: 3 | L14: 1.5 | M14: 1.5 | N14: =SUM(K14:M14) -> 6 | O14: =SUM(D14:F14) -> 19
C15: rang | D15: =RANK(D5,D$5:D$14,1) -> 2 | E15: =RANK(E5,E$5:E$14,1) -> 2 | F15: =RANK(F5,F$5:F$14,1) -> 5 | G15: répétition | H15: =COUNTIF(D$15:D$24,D$15:D$24) -> 3 | I15: =COUNTIF(E$15:E$24,E$15:E$24) -> 1 | J15: =COUNTIF(F$15:F$24,F$15:F$24) -> 3 | K15: rang corrigé | L15: =IF(H15=1,D15,IF(H15=2,D15+0.5,IF(H15=3,D15+1,IF(H15=4,D15+1.5,"")))) -> 3 | M15: =IF(I15=1,E15,IF(I15=2,E15+0.5,IF(I15=3,E15+1,IF(I15=4,E15+1.5,"")))) -> 2 | N15: =IF(J15=1,F15,IF(J15=2,F15+0.5,IF(J15=3,F15+1,IF(J15=4,F15+1.5,"")))) -> 6 | O15: =SUM(L15:N15) -> 11
D16: =RANK(D6,D$5:D$14,1) -> 9 | E16: =RANK(E6,E$5:E$14,1) -> 10 | F16: =RANK(F6,F$5:F$14,1) -> 8 | H16: =COUNTIF(D$15:D$24,D$15:D$24) -> 1 | I16: =COUNTIF(E$15:E$24,E$15:E$24) -> 1 | J16: =COUNTIF(F$15:F$24,F$15:F$24) -> 2 | L16: =IF(H16=1,D16,IF(H16=2,D16+0.5,IF(H16=3,D16+1,IF(H16=4,D16+1.5,"")))) -> 9 | M16: =IF(I16=1,E16,IF(I16=2,E16+0.5,IF(I16=3,E16+1,IF(I16=4,E16+1.5,"")))) -> 10 | N16: =IF(J16=1,F16,IF(J16=2,F16+0.5,IF(J16=3,F16+1,IF(J16=4,F16+1.5,"")))) -> 8.5 | O16: =SUM(L16:N16) -> 27.5
D17: =RANK(D7,D$5:D$14,1) -> 7 | E17: =RANK(E7,E$5:E$14,1) -> 7 | F17: =RANK(F7,F$5:F$14,1) -> 5 | H17: =COUNTIF(D$15:D$24,D$15:D$24) -> 2 | I17: =COUNTIF(E$15:E$24,E$15:E$24) -> 2 | J17: =COUNTIF(F$15:F$24,F$15:F$24) -> 3 | L17: =IF(H17=1,D17,IF(H17=2,D17+0.5,IF(H17=3,D17+1,IF(H17=4,D17+1.5,"")))) -> 7.5 | M17: =IF(I17=1,E17,IF(I17=2,E17+0.5,IF(I17=3,E17+1,IF(I17=4,E17+1.5,"")))) -> 7.5 | N17: =IF(J17=1,F17,IF(J17=2,F17+0.5,IF(J17=3,F17+1,IF(J17=4,F17+1.5,"")))) -> 6 | O17: =SUM(L17:N17) -> 21
D18: =RANK(D8,D$5:D$14,1) -> 5 | E18: =RANK(E8,E$5:E$14,1) -> 3 | F18: =RANK(F8,F$5:F$14,1) -> 2 | H18: =COUNTIF(D$15:D$24,D$15:D$24) -> 1 | I18: =COUNTIF(E$15:E$24,E$15:E$24) -> 4 | J18: =COUNTIF(F$15:F$24,F$15:F$24) -> 2 | L18: =IF(H18=1,D18,IF(H18=2,D18+0.5,IF(H18=3,D18+1,IF(H18=4,D18+1.5,"")))) -> 5 | M18: =IF(I18=1,E18,IF(I18=2,E18+0.5,IF(I18=3,E18+1,IF(I18=4,E18+1.5,"")))) -> 4.5 | N18: =IF(J18=1,F18,IF(J18=2,F18+0.5,IF(J18=3,F18+1,IF(J18=4,F18+1.5,"")))) -> 2.5 | O18: =SUM(L18:N18) -> 12
D19: =RANK(D9,D$5:D$14,1) -> 10 | E19: =RANK(E9,E$5:E$14,1) -> 9 | F19: =RANK(F9,F$5:F$14,1) -> 10 | H19: =COUNTIF(D$15:D$24,D$15:D$24) -> 1 | I19: =COUNTIF(E$15:E$24,E$15:E$24) -> 1 | J19: =COUNTIF(F$15:F$24,F$15:F$24) -> 1 | L19: =IF(H19=1,D19,IF(H19=2,D19+0.5,IF(H19=3,D19+1,IF(H19=4,D19+1.5,"")))) -> 10 | M19: =IF(I19=1,E19,IF(I19=2,E19+0.5,IF(I19=3,E19+1,IF(I19=4,E19+1.5,"")))) -> 9 | N19: =IF(J19=1,F19,IF(J19=2,F19+0.5,IF(J19=3,F19+1,IF(J19=4,F19+1.5,"")))) -> 10 | O19: =SUM(L19:N19) -> 29
D20: =RANK(D10,D$5:D$14,1) -> 6 | E20: =RANK(E10,E$5:E$14,1) -> 3 | F20: =RANK(F10,F$5:F$14,1) -> 4 | H20: =COUNTIF(D$15:D$24,D$15:D$24) -> 1 | I20: =COUNTIF(E$15:E$24,E$15:E$24) -> 4 | J20: =COUNTIF(F$15:F$24,F$15:F$24) -> 1 | L20: =IF(H20=1,D20,IF(H20=2,D20+0.5,IF(H20=3,D20+1,IF(H20=4,D20+1.5,"")))) -> 6 | M20: =IF(I20=1,E20,IF(I20=2,E20+0.5,IF(I20=3,E20+1,IF(I20=4,E20+1.5,"")))) -> 4.5 | N20: =IF(J20=1,F20,IF(J20=2,F20+0.5,IF(J20=3,F20+1,IF(J20=4,F20+1.5,"")))) -> 4 | O20: =SUM(L20:N20) -> 14.5
D21: =RANK(D11,D$5:D$14,1) -> 2 | E21: =RANK(E11,E$5:E$14,1) -> 3 | F21: =RANK(F11,F$5:F$14,1) -> 2 | H21: =COUNTIF(D$15:D$24,D$15:D$24) -> 3 | I21: =COUNTIF(E$15:E$24,E$15:E$24) -> 4 | J21: =COUNTIF(F$15:F$24,F$15:F$24) -> 2 | L21: =IF(H21=1,D21,IF(H21=2,D21+0.5,IF(H21=3,D21+1,IF(H21=4,D21+1.5,"")))) -> 3 | M21: =IF(I21=1,E21,IF(I21=2,E21+0.5,IF(I21=3,E21+1,IF(I21=4,E21+1.5,"")))) -> 4.5 | N21: =IF(J21=1,F21,IF(J21=2,F21+0.5,IF(J21=3,F21+1,IF(J21=4,F21+1.5,"")))) -> 2.5 | O21: =SUM(L21:N21) -> 10
D22: =RANK(D12,D$5:D$14,1) -> 7 | E22: =RANK(E12,E$5:E$14,1) -> 7 | F22: =RANK(F12,F$5:F$14,1) -> 8 | H22: =COUNTIF(D$15:D$24,D$15:D$24) -> 2 | I22: =COUNTIF(E$15:E$24,E$15:E$24) -> 2 | J22: =COUNTIF(F$15:F$24,F$15:F$24) -> 2 | L22: =IF(H22=1,D22,IF(H22=2,D22+0.5,IF(H22=3,D22+1,IF(H22=4,D22+1.5,"")))) -> 7.5 | M22: =IF(I22=1,E22,IF(I22=2,E22+0.5,IF(I22=3,E22+1,IF(I22=4,E22+1.5,"")))) -> 7.5 | N22: =IF(J22=1,F22,IF(J22=2,F22+0.5,IF(J22=3,F22+1,IF(J22=4,F22+1.5,"")))) -> 8.5 | O22: =SUM(L22:N22) -> 23.5
D23: =RANK(D13,D$5:D$14,1) -> 2 | E23: =RANK(E13,E$5:E$14,1) -> 3 | F23: =RANK(F13,F$5:F$14,1) -> 5 | H23: =COUNTIF(D$15:D$24,D$15:D$24) -> 3 | I23: =COUNTIF(E$15:E$24,E$15:E$24) -> 4 | J23: =COUNTIF(F$15:F$24,F$15:F$24) -> 3 | L23: =IF(H23=1,D23,IF(H23=2,D23+0.5,IF(H23=3,D23+1,IF(H23=4,D23+1.5,"")))) -> 3 | M23: =IF(I23=1,E23,IF(I23=2,E23+0.5,IF(I23=3,E23+1,IF(I23=4,E23+1.5,"")))) -> 4.5 | N23: =IF(J23=1,F23,IF(J23=2,F23+0.5,IF(J23=3,F23+1,IF(J23=4,F23+1.5,"")))) -> 6 | O23: =SUM(L23:N23) -> 13.5
D24: =RANK(D14,D$5:D$14,1) -> 1 | E24: =RANK(E14,E$5:E$14,1) -> 1 | F24: =RANK(F14,F$5:F$14,1) -> 1 | H24: =COUNTIF(D$15:D$24,D$15:D$24) -> 1 | I24: =COUNTIF(E$15:E$24,E$15:E$24) -> 1 | J24: =COUNTIF(F$15:F$24,F$15:F$24) -> 1 | L24: =IF(H24=1,D24,IF(H24=2,D24+0.5,IF(H24=3,D24+1,IF(H24=4,D24+1.5,"")))) -> 1 | M24: =IF(I24=1,E24,IF(I24=2,E24+0.5,IF(I24=3,E24+1,IF(I24=4,E24+1.5,"")))) -> 1 | N24: =IF(J24=1,F24,IF(J24=2,F24+0.5,IF(J24=3,F24+1,IF(J24=4,F24+1.5,"")))) -> 1 | O24: =SUM(L24:N24) -> 3
H25: =COUNTIF(D$15:D$24,D$15:D$24) -> 0 | L25: =IF(H25=1,F25,IF(H25=2,F25+0.5,IF(H25=3,F25+1,IF(H25=4,F25+1.5,"")))) | O25: somme
C26: colonne q | D26: =COUNT(D5:F5) -> 3
C27: ligne p | D27: =COUNT(D5:D14) -> 10
C29: Etude du facteur 2 | K29: Etude du facteur 1
C30: X²obs | D30: =12/(D26*D27*(D26+1))*(K4^2+L4^2+M4^2)-3*D27*(D26+1) -> 5.45 | G30: y | H30: x | K30: X²obs | L30: =12/(D27*D26*(D27+1))*(O15^2+O16^2+O17^2+O18^2+O19^2+O20^2+O21^2+O22^2+O23^2+O24^2)-3*D26*(D27+1) -> 23.072727 | O30: y | P30: x
C31: correction | D31: =1-((G31*(H31^3-H31)+G32*(H32^3-H32))/(D27*(D26^3-3))) -> 0.85 | F31: nb doublon | G31: =COUNTIF(J5:J14,"doublon") -> 6 | H31: 2 | K31: correction | L31: =1-(O31*(P31^3-P31)+O32*(P32^3-P32)+O33*(P33^3-P33))/(D26*(D27^3-D27)) -> 0.95555556 | N31: nb doublon | O31: =(COUNTIF(H15:J24,2))/2 -> 4 | P31: 2
C32: X² corrigé | D32: =D30/D31 -> 6.4117647 | F32: nb triplon | G32: =COUNTIF(J5:J14,"triplon") -> 0 | H32: 3 | K32: X² corrigé | L32: =L30/L31 -> 24.145877 | N32: nb triplon | O32: =(COUNTIF(H15:J24,3))/3 -> 2 | P32: 3
C33: X²(5%,ddl) | D33: =_xlfn.CHISQ.INV(0.95,2) -> 5.9914645 | K33: X²(5%,ddl) | L33: =_xlfn.CHISQ.INV(0.95,9) -> 16.918978 | N33: nb quadruplon | O33: =(COUNTIF(H15:J24,4))/4 -> 1 | P33: 4
C34: Bilan | D34: =IF(D32<D33,"OK","Différence") -> Différence | K34: Bilan | L34: =IF(L32<L33,"OK","Différence") -> Différence
C35: *Si différence, il existe au moins 2 différences parmi les p facteurs 2 | K35: *Si différence, il existe au moins 2 différences parmi les q facteurs 1

Sheet khi-2 ajust et indep
B2: Test d'indépendance
D3: y a-t-il une différence entre au moins 2 classes ?
D5: critère qualitatif commun
D6: Salaire | E6: 1000-2000 | F6: 2000-3000 | G6: 3000-4000 | H6: 4000-5000 | I6: Total
C7: classe | D7: Homme | E7: 50 | F7: 70 | G7: 110 | H7: 60 | I7: =SUM(E7:H7) -> 290
D8: Femme | E8: 60 | F8: 75 | G8: 100 | H8: 50 | I8: =SUM(E8:H8) -> 285
D9: Total | E9: =SUM(E7:E8) -> 110 | F9: =SUM(F7:F8) -> 145 | G9: =SUM(G7:G8) -> 210 | H9: =SUM(H7:H8) -> 110 | I9: =SUM(E9:H9) -> 575
D10: ddl | E10: =(COUNT(E7:H7)-1)*(COUNT(E7:E8)-1) -> 3
D11: X² 5% | E11: =_xlfn.CHISQ.INV(0.95,E10) -> 7.8147279 | F11: H0: pas de différence
D12: X² observé | E12: =I24 -> 2.4234911 | F12: Si X² < X²5%, égalité des classes
D14: valeur attendue
D15: Salaire | E15: 1000-2000 | F15: 2000-3000 | G15: 3000-4000 | H15: 4000-5000 | I15: Total
D16: Homme | E16: =E18/I18*I16 -> 55.478261 | F16: =F18/I18*I16 -> 73.130435 | G16: =G18/I18*I16 -> 105.91304 | H16: =H18/I18*I16 -> 55.478261 | I16: =I7 -> 290
D17: Femme | E17: =E18/$I$18*$I$17 -> 54.521739 | F17: =F18/$I$18*$I$17 -> 71.869565 | G17: =G18/$I$18*$I$17 -> 104.08696 | H17: =H18/$I$18*$I$17 -> 54.521739 | I17: =I8 -> 285
D18: Total | E18: =E9 -> 110 | F18: =F9 -> 145 | G18: =G9 -> 210 | H18: =H9 -> 110 | I18: =I9 -> 575
D20: xi² observé
D21: Salaire | E21: 1000-2000 | F21: 2000-3000 | G21: 3000-4000 | H21: 4000-5000 | I21: Total
D22: Homme | E22: =(E7-E16)^2/E16 -> 0.54095679 | F22: =(F7-F16)^2/F16 -> 0.13400196 | G22: =(G7-G16)^2/G16 -> 0.15770686 | H22: =(H7-H16)^2/H16 -> 0.368543 | I22: =SUM(E22:H22) -> 1.2012086
D23: Femme | E23: =(E8-E17)^2/E17 -> 0.55044726 | F23: =(F8-F17)^2/F17 -> 0.13635288 | G23: =(G8-G17)^2/G17 -> 0.16047365 | H23: =(H8-H17)^2/H17 -> 0.37500867 | I23: =SUM(E23:H23) -> 1.2222825
D24: Total | E24: =SUM(E22:E23) -> 1.0914041 | F24: =SUM(F22:F23) -> 0.27035484 | G24: =SUM(G22:G23) -> 0.31818051 | H24: =SUM(H22:H23) -> 0.74355167 | I24: =SUM(I22:I23) -> 2.4234911
D25: calcul : (valeur observée - valeur attendue)²/valeur attendue
B26: Test d'ajustement
C27: La loi uniforme est elle respectée ? C’est-à-dire y a-t-il autant de panne sur chaque ligne
D29: ligne | E29: Panne réelle | F29: Panne th. | G29: Pr-Pth | H29: (Pr-Pth)² | I29: (Pr-Pth)²/Pth
D30: rouge | E30: 56 | F30: =F34/COUNT(E30:E33) -> 55 | G30: =E30-F30 -> 1 | H30: =G30^2 -> 1 | I30: =H30/F30 -> 0.018181818
D31: bleue | E31: 66 | F31: =F30 -> 55 | G31: =E31-F31 -> 11 | H31: =G31^2 -> 121 | I31: =H31/F31 -> 2.2
D32: verte | E32: 44 | F32: =F31 -> 55 | G32: =E32-F32 -> -11 | H32: =G32^2 -> 121 | I32: =H32/F32 -> 2.2
D33: jaune | E33: 54 | F33: =F32 -> 55 | G33: =E33-F33 -> -1 | H33: =G33^2 -> 1 | I33: =H33/F33 -> 0.018181818
D34: somme | E34: =SUM(E30:E33) -> 220 | F34: =E34 -> 220 | G34: =SUM(G30:G33) -> 0 | H34: =SUM(H30:H33) -> 244 | I34: =SUM(I30:I33) -> 4.4363636 | J34: Xhi²
I35: =CHIINV(0.05,COUNT(E30:E33)-1) -> 7.8147279 | J35: Xhi² 0,05%
C36: réponse: pas de différence | I36: Si xhi² < xhi²tabulé, pas de différence

Sheet Feuil1

Sheet Récapitulatif
B1: Profil d'exactitude
B2: Probabilité tolérance (bêta) | C2: =#REF! -> #REF! | E2: 20 | F2: 100
B3: Limite d'acceptabilité | C3: =#REF! -> #REF! | E3: 0.01 | F3: =E3*F2/E2 -> 0.05
B5: Niveaux | C5: Niveau A | D5: Niveau B | E5: Niveau C | F5: Niveau D | G5: Niveau E
A6: 2 | B6: Valeur cible | C6: ='80%'!B2 -> 80 | D6: ='90%'!B2 -> 90 | E6: ='100%'!B2 -> 100 | F6: ='110%'!B2 -> 110 | G6: ='120%'!B2 -> 120
A7: 30 | B7: Moyenne niveau | C7: ='80%'!B22 -> #REF! | D7: ='90%'!B22 -> #REF! | E7: ='100%'!B22 -> #REF! | F7: ='110%'!B22 -> #REF! | G7: ='120%'!B22 -> #REF! | K7: =ADDRESS($A8,2,,,C$5) -> 'Niveau A'!$B$31
A8: 31 | B8: Ecart-type de répétabilité (sr) | C8: ='80%'!B23 -> #DIV/0! | D8: ='90%'!B23 -> #DIV/0! | E8: ='100%'!B23 -> #DIV/0! | F8: ='110%'!B23 -> #DIV/0! | G8: ='120%'!B23 -> #DIV/0!
A9: 32 | B9: Ecart-type inter-séries (sL) | C9: ='80%'!B24 -> #REF! | D9: ='90%'!B24 -> #REF! | E9: ='100%'!B24 -> #REF! | F9: ='110%'!B24 -> #REF! | G9: ='120%'!B24 -> #REF!
A10: 33 | B10: Ecart-type de fidélité (sFI) | C10: ='80%'!B25 -> #DIV/0! | D10: ='90%'!B25 -> #DIV/0! | E10: ='100%'!B25 -> #DIV/0! | F10: ='110%'!B25 -> #DIV/0! | G10: ='120%'!B25 -> #DIV/0!
A11: 37 | B11: Rapport des variances (R) | C11: ='80%'!B29 -> #REF! | D11: ='90%'!B29 -> #REF! | E11: ='100%'!B29 -> #REF! | F11: ='110%'!B29 -> #REF! | G11: ='120%'!B29 -> #REF!
A12: 39 | B12: Coefficient intermédiaire | C12: ='80%'!B31 -> #REF! | D12: ='90%'!B31 -> #REF! | E12: ='100%'!B31 -> #REF! | F12: ='110%'!B31 -> #REF! | G12: ='120%'!B31 -> #REF!
A13: 40 | B13: Nombre de degrés liberté | C13: ='80%'!B32 -> #REF! | D13: ='90%'!B32 -> #REF! | E13: ='100%'!B32 -> #REF! | F13: ='110%'!B32 -> #REF! | G13: ='120%'!B32 -> #REF!
A14: 47 | B14: Valeur basse tolérance | C14: ='80%'!B39 -> #REF! | D14: ='90%'!B39 -> #REF! | E14: ='100%'!B39 -> #REF! | F14: ='110%'!B39 -> #REF! | G14: ='120%'!B39 -> #REF!
A15: 48 | B15: Valeur haute tolérance | C15: ='80%'!B40 -> #REF! | D15: ='90%'!B40 -> #REF! | E15: ='100%'!B40 -> #REF! | F15: ='110%'!B40 -> #REF! | G15: ='120%'!B40 -> #REF!
A16: 35 | B16: Biais (%) | C16: ='80%'!B27 -> #REF! | D16: ='90%'!B27 -> #REF! | E16: ='100%'!B27 -> #REF! | F16: ='110%'!B27 -> #REF! | G16: ='120%'!B27 -> #REF!
B17: Recouvrement (justesse) | C17: =C7/C$6 -> #REF! | D17: =D7/D$6 -> #REF! | E17: =E7/E$6 -> #REF! | F17: =F7/F$6 -> #REF! | G17: =G7/G$6 -> #REF!
B18: Limite basse tolérance (%) | C18: =C14/C$6 -> #REF! | D18: =D14/D$6 -> #REF! | E18: =E14/E$6 -> #REF! | F18: =F14/F$6 -> #REF! | G18: =G14/G$6 -> #REF!
B19: Limite haute tolérance (%) | C19: =C15/C$6 -> #REF! | D19: =D15/D$6 -> #REF! | E19: =E15/E$6 -> #REF! | F19: =F15/F$6 -> #REF! | G19: =G15/G$6 -> #REF!
B20: Limite d'acceptabilité basse | C20: =1-$C$3 -> #REF! | D20: =1-$C$3 -> #REF! | E20: =1-$C$3 -> #REF! | F20: =1-$C$3 -> #REF! | G20: =1-$C$3 -> #REF!
B21: Limite d'acceptabilité haute | C21: =1+$C$3 -> #REF! | D21: =1+$C$3 -> #REF! | E21: =1+$C$3 -> #REF! | F21: =1+$C$3 -> #REF! | G21: =1+$C$3 -> #REF!
B27: Incertitude
B28: Ecart-type de l'IT (sIT) | C28: =C$12*C$10 -> #REF! | D28: =D$12*D$10 -> #REF! | E28: =E$12*E$10 -> #REF! | F28: =F$12*F$10 -> #REF! | G28: =G$12*G$10 -> #REF!
B29: Incertitude élargie relative | C29: =2*C28/C7 -> #REF! | D29: =2*D28/D7 -> #REF! | E29: =2*E28/E7 -> #REF! | F29: =2*F28/F7 -> #REF! | G29: =2*G28/G7 -> #REF!

Sheet 80%
A1: Niveau A
A2: Valeur cible | B2: 80
B4: Répétition 1 | C4: Répétition 2 | D4: Répétition 3 | E4: Répétition 4 | F4: Répétition 5 | H4: nk | I4: SCEk
A5: Jour (Série) 1 | B5: =#REF!*$B$2 -> #REF! | C5: =#REF!*$B$2 -> #REF! | H5: =COUNT(B5:F5) -> 0 | I5: =IF(H5=0,"",DEVSQ(B5:F5))
A6: Jour (Série) 2
A7: Jour (Série) 3 | B7: =#REF!*$B$2 -> #REF! | C7: =#REF!*$B$2 -> #REF! | H7: =COUNT(B7:F7) -> 0 | I7: =IF(H7=0,"",DEVSQ(B7:F7))
A8: Jour (Série) 4 | B8: =#REF!*$B$2 -> #REF! | C8: =#REF!*$B$2 -> #REF! | H8: =COUNT(B8:F8) -> 0 | I8: =IF(H8=0,"",DEVSQ(B8:F8))
A9: Jour (Série) 5 | B9: =#REF!*$B$2 -> #REF! | C9: =#REF!*$B$2 -> #REF! | H9: =COUNT(B9:F9) -> 0 | I9: =IF(H9=0,"",DEVSQ(B9:F9))
A11: Nombre de séries (K) | B11: =COUNT(B5:B9) -> 0
A12: Nombre de mesures (IK) | B12: =COUNT(B5:F9) -> 0
A13: Nombre de répétitions (I) | B13: =IF(H5*B11<>B12,"Calcul impossible",H5) -> 0
A14: SCE résiduelle | B14: =SUM(I5:I9) -> 0
A15: SCE totale | B15: =DEVSQ(B5:F9) -> #REF!
A16: SCE inter-séries | B16: =B15-B14 -> #REF!
A17: Valeur intermédiaire de s²L | B17: =((B16/(B11-1))-B18)/B13 -> #REF!
A18: Variance de répétabilité (s²r) | B18: =B14/(B12-B11) -> #DIV/0!
A19: Variance inter-séries (s²L) | B19: =IF(B17<0,0,B17) -> #REF!
A20: Variance de fidélité (s²FI) | B20: =SUM(B18:B19) -> #DIV/0!
A21: Fidélité
A22: Moyenne niveau | B22: =AVERAGE(B5:F9) -> #REF!
A23: Ecart-type de répétabilité (sr) | B23: =SQRT(B18) -> #DIV/0!
A24: Ecart-type inter-séries (sL) | B24: =SQRT(B19) -> #REF!
A25: Ecart-type de fidélité (sFI) | B25: =SQRT(B20) -> #DIV/0!
A26: Justesse
A27: Biais (%) | B27: =B22/B2-1 -> #REF!
A28: Facteur de couverture
A29: Rapport des variances (R) | B29: =B19/B18 -> #REF!
A30: Coefficient B² | B30: =(B29+1)/(B13*B29+1) -> #REF!
A31: Coefficient intermédiaire | B31: =SQRT(1+1/(B12*B30)) -> #REF!
A32: Nombre de degrés liberté | B32: =(B29+1)^2/((B29+1/B13)^2/(B11-1)+(1-1/B13)/B12) -> #REF!
A33: Probabilité tolérance (bêta) | B33: =Récapitulatif!C2 -> #REF!
A34: t Student bas | B34: =TINV(1-B33,ROUNDDOWN(B32,0)) -> #REF!
A35: t Student haut | B35: =TINV(1-B33,ROUNDUP(B32,0)) -> #REF!
A36: t Student interpolé | B36: =B34-(B34-B35)*(B32-ROUNDDOWN(B32,0)) -> #REF!
A37: Facteur de couverture (ktol) | B37: =B36*B31 -> #REF!
A38: Intervalle de tolérance
A39: Valeur basse tolérance | B39: =B22-B37*B25 -> #REF!
A40: Valeur haute tolérance | B40: =B22+B37*B25 -> #REF!

Sheet 90%
A1: Niveau B
A2: Valeur cible | B2: 90
B4: Répétition 1 | C4: Répétition 2 | D4: Répétition 3 | E4: Répétition 4 | F4: Répétition 5 | H4: nk | I4: SCEk
A5: Jour (Série) 1 | B5: =#REF!*$B$2 -> #REF! | C5: =#REF!*$B$2 -> #REF! | H5: =COUNT(B5:F5) -> 0 | I5: =IF(H5=0,"",DEVSQ(B5:F5))
A6: Jour (Série) 2 | B6: =#REF!*$B$2 -> #REF! | C6: =#REF!*$B$2 -> #REF! | H6: =COUNT(B6:F6) -> 0 | I6: =IF(H6=0,"",DEVSQ(B6:F6))
A7: Jour (Série) 3 | I7: =IF(H7=0,"",DEVSQ(B7:F7))
A8: Jour (Série) 4 | B8: =#REF!*$B$2 -> #REF! | C8: =#REF!*$B$2 -> #REF! | H8: =COUNT(B8:F8) -> 0 | I8: =IF(H8=0,"",DEVSQ(B8:F8))
A9: Jour (Série) 5 | B9: =#REF!*$B$2 -> #REF! | C9: =#REF!*$B$2 -> #REF! | H9: =COUNT(B9:F9) -> 0 | I9: =IF(H9=0,"",DEVSQ(B9:F9))
A11: Nombre de séries (K) | B11: =COUNT(B5:B9) -> 0
A12: Nombre de mesures (IK) | B12: =COUNT(B5:F9) -> 0
A13: Nombre de répétitions (I) | B13: =IF(H5*B11<>B12,"Calcul impossible",H5) -> 0
A14: SCE résiduelle | B14: =SUM(I5:I9) -> 0
A15: SCE totale | B15: =DEVSQ(B5:F9) -> #REF!
A16: SCE inter-séries | B16: =B15-B14 -> #REF!
A17: Valeur intermédiaire de s²L | B17: =((B16/(B11-1))-B18)/B13 -> #REF!
A18: Variance de répétabilité (s²r) | B18: =B14/(B12-B11) -> #DIV/0!
A19: Variance inter-séries (s²L) | B19: =IF(B17<0,0,B17) -> #REF!
A20: Variance de fidélité (s²FI) | B20: =SUM(B18:B19) -> #DIV/0!
A21: Fidélité
A22: Moyenne niveau | B22: =AVERAGE(B5:F9) -> #REF!
A23: Ecart-type de répétabilité (sr) | B23: =SQRT(B18) -> #DIV/0!
A24: Ecart-type inter-séries (sL) | B24: =SQRT(B19) -> #REF!
A25: Ecart-type de fidélité (sFI) | B25: =SQRT(B20) -> #DIV/0!
A26: Justesse
A27: Biais (%) | B27: =B22/B2-1 -> #REF!
A28: Facteur de couverture
A29: Rapport des variances (R) | B29: =B19/B18 -> #REF!
A30: Coefficient B² | B30: =(B29+1)/(B13*B29+1) -> #REF!
A31: Coefficient intermédiaire | B31: =SQRT(1+1/(B12*B30)) -> #REF!
A32: Nombre de degrés liberté | B32: =(B29+1)^2/((B29+1/B13)^2/(B11-1)+(1-1/B13)/B12) -> #REF!
A33: Probabilité tolérance (bêta) | B33: =Récapitulatif!C2 -> #REF!
A34: t Student bas | B34: =TINV(1-B33,ROUNDDOWN(B32,0)) -> #REF!
A35: t Student haut | B35: =TINV(1-B33,ROUNDUP(B32,0)) -> #REF!
A36: t Student interpolé | B36: =B34-(B34-B35)*(B32-ROUNDDOWN(B32,0)) -> #REF!
